File: MATLAB/ASEN 1022/brittleOriginal.csv
"File Path: C:\Users\neba4211\Desktop\Test Run 1 03-22-19 9 37 43 AM\DAQ- Crosshead, … - (Timed).csv   "
"Test: MTS EM Tension (ASEN 1022 Extensometer) 50"
"Test Run: Test Run 1"
"Date: 3/22/2019 9:34:58 AM"
""
""
"Crosshead ","Load ","Time ","Extensometer "
"in","lbf","sec","in"
"0.00700868705588239","406.941755790152","14.0780000686646","-6.9304422778066E-05"
"0.0071142044827694","413.120022563193","14.2779998779297","-6.4341311980835E-05"
"0.00721737698882848","419.062091756491","14.4779996871948","-6.30767294214319E-05"
"0.00731351473240372","424.382121849051","14.67799949646","-5.97622120469569E-05"
"0.00741199739680692","430.0787453408","14.8780002593994","-5.82645043323282E-05"
"0.00751751482369393","436.213625524603","15.0780000686646","-5.66495604231939E-05"
"0.00761365256726918","441.425202865316","15.2779998779297","-5.55042819055022E-05"
"0.00771213523167237","447.121579374584","15.4779996871948","-4.94585232961007E-05"
"0.00781765265855938","453.308874729446","15.67799949646","-4.59478379403792E-05"
"0.00791613532296257","458.486670355199","15.8780002593994","-4.39881722648022E-05"
"0.00801461798736576","463.895504371083","16.0780010223389","-4.04334041663752E-05"
"0.00811779049342484","469.702721129519","16.2779998779297","-3.46032141523189E-05"
"0.00821392823700009","474.913722177775","16.4780006408691","-3.44391873199573E-05"
"0.00831006598057533","480.060727320843","16.67799949646","-2.88362613227803E-05"
"0.00841323848663441","486.042423481162","16.8780002593994","-2.25886123454382E-05"
"0.0085117211510376","491.49629063616","17.0780010223389","-2.12621913076902E-05"
"0.00860785946752289","496.507565184432","17.2779998779297","-1.74011669815362E-05"
"0.00871103140067192","502.228392959361","17.4780006408691","-1.34605260620991E-05"
"0.00881420390673099","507.819747029024","17.67799949646","-5.55949057568825E-06"
"0.00891034165030624","512.827289397576","17.8780002593994","-5.37355664776649E-06"
"0.00901351415636531","518.352342392223","18.0780010223389","2.84328067651787E-06"
"0.00911668666242439","524.099734505156","18.2779998779297","6.09463108152498E-06"
"0.00921282440599963","528.93126069194","18.4780006408691","9.0370383442473E-06"
"0.00930896214957488","533.915531822242","18.67799949646","1.46409423167803E-05"
"0.00941682449728984","540.136032599608","18.8780002593994","1.9102783676854E-05"
"0.00951296224086509","545.007734603372","19.0780010223389","2.31881649489778E-05"
"0.00961379039900627","550.357265381214","19.2779998779297","2.65441892088705E-05"
"0.00971696233215529","555.83045205476","19.4780006408691","3.5763388331268E-05"
"0.00981544556946853","560.639530278232","19.67799949646","3.38522767822896E-05"
"0.00991158331304378","565.401681830231","19.8780002593994","4.1116048868296E-05"
"0.0100124108982749","570.89133400254","20.0780010223389","4.79292025840378E-05"
"0.0101155828314239","576.377253995129","20.2779998779297","5.11593007677149E-05"
"0.0102093762270813","581.011962586709","20.4780006408691","5.63613374344111E-05"
"0.0103125481602303","586.505237168746","20.67799949646","6.1474725222843E-05"
"0.0104157212391994","591.883143489455","20.8780002593994","6.46969235140563E-05"
"0.0105118589827747","596.664998754973","21.0780010223389","6.87510632851054E-05"
"0.0106126865680058","601.855857009744","21.2779998779297","7.27468826035753E-05"
"0.0107182028490727","607.158680656098","21.4780006408691","7.91418209357332E-05"
"0.0108143417384681","611.869350081967","21.67799949646","8.23930227981448E-05"
"0.0109081339883053","616.662456771639","21.8780002593994","8.7558952704215E-05"
"0.0110183412568482","622.642780807061","22.0780010223389","9.4077818641209E-05"
"0.0111144790004235","627.29186926756","22.2779998779297","9.81350333279083E-05"
"0.0112106167439987","632.134262683527","22.4780006408691","0.00010120098830687"
"0.0113161341708857","637.487525641089","22.67799949646","0.000105188460146901"
"0.0114169617561169","642.311313043455","22.8780002593994","0.000109037001300204"
"0.0115107551517742","646.98559371706","23.0780010223389","0.000115709908426451"
"0.0116162725786613","652.361304637935","23.2779998779297","0.000120319506868685"
"0.0117170990180723","657.318901660241","23.4780006408691","0.000125270156872364"
"0.0118085480658117","661.620952291829","23.67799949646","0.000127843265982224"
"0.0119117199989608","667.063183827703","23.8780002593994","0.000136505540589367"
"0.0120148930779299","672.295315599371","24.0780010223389","0.00013695565990127"
"0.0121110308215051","676.756532718993","24.2779998779297","0.000140197310278969"
"0.0122142027546542","681.925052780443","24.4780006408691","0.000151066747702581"
"0.0123173746878032","687.098951571489","24.67799949646","0.000152318502447933"
"0.0124135135771985","691.383548774389","24.8780002593994","0.000151599446626923"
"0.0125119956686917","696.105414739417","25.0780010223389","0.000161211982066468"
"0.0126151687476608","701.445340642982","25.2779998779297","0.000166014472160609"
"0.012711306491236","705.959357128635","25.4780006408691","0.000166884812041265"
"0.0128097885827292","710.780400281207","25.67799949646","0.000173963509564422"
"0.0129153060096162","716.311929705367","25.8780002593994","0.000179651378427988"
"0.0130161335948473","720.977812974604","26.0780010223389","0.000181624784993006"
"0.0131099269905047","725.06745867216","26.2779998779297","0.00018833758993309"
"0.0132154444173917","730.518801117348","26.4780006408691","0.000191694807009606"
"0.0133162720026228","735.155046488813","26.67799949646","0.000196092500347703"
"0.0134100642524601","739.527459685111","26.8780002593994","0.000201152298667314"
"0.0135132373314292","744.732039188851","27.0780010223389","0.000205705214821638"
"0.0136164092645782","749.667243132841","27.2779998779297","0.000206605542962637"
"0.0137125470081535","754.038503744226","27.4780006408691","0.000212340444160486"
"0.0138110302454667","758.728042446684","27.67799949646","0.000220302622688533"
"0.0139188920202716","763.896342968151","27.8780002593994","0.000223188907705297"
"0.014012685415929","768.161071802544","28.0780010223389","0.000224085637255055"
"0.0141135130011601","772.75154308745","28.2779998779297","0.000230117449085466"
"0.014219029282227","777.834332785345","28.4780006408691","0.000238152172348387"
"0.0143128226778844","781.914648033602","28.67799949646","0.000237931154393793"
"0.0144113059151976","786.687447274801","28.8780002593994","0.000243623588634307"
"0.0145097880066908","791.156677603821","29.0780010223389","0.000250665476686857"
"0.0146129610856599","796.219818473193","29.2779998779297","0.000250468127078635"
"0.0147090988292351","800.514459630338","29.4780006408691","0.000257410310879331"
"0.0148146162561222","805.558116326175","29.67799949646","0.000262429575813021"
"0.0149177881892712","810.301058129619","29.8780002593994","0.000266197569394213"
"0.0150139259328464","814.239770088521","30.0780010223389","0.000270734211322476"
"0.0151124091701597","819.055214971514","30.2779998779297","0.000275141196545419"
"0.0152132367553908","823.684819258478","30.4780006408691","0.000278738176477175"
"0.0153093744989661","828.074137033506","30.67799949646","0.00028234947916014"
"0.0154148919258531","833.021305906596","30.8780002593994","0.000290610054306187"
"0.0155180638590021","837.842349059168","31.0780010223389","0.000293414090924134"
"0.0156142016025773","841.817065575364","31.2779998779297","0.000295494237792537"
"0.0157126848398906","846.128391771255","31.4780006408691","0.000303906866846107"
"0.0158205466146955","851.361676127836","31.67799949646","0.000307722161313167"
"0.0159143400103528","855.20565658386","31.8780002593994","0.000307573741803763"
"0.0160104777539281","859.565665771091","32.0779991149902","0.00031388921572187"
"0.0161159951808151","864.600925062559","32.2779998779297","0.000319747328386994"
"0.0162121329243904","868.726246007433","32.4780006408691","0.000321162380399567"
"0.0163082706679656","872.820831354618","32.6780014038086","0.000324889052843521"
"0.0164090982531967","877.764816897948","32.8779983520508","0.000330979480533256"
"0.0165122701863458","882.23042481724","33.0779991149902","0.000336379659035349"
"0.016610753423659","886.390487964502","33.2779998779297","0.000339176498470813"
"0.016713925356808","891.011969272077","33.4780006408691","0.000345812300719709"
"0.0168170984357771","895.699477229687","33.6780014038086","0.000347015483435023"
"0.0169108906856144","899.238187338661","33.8779983520508","0.000348224753319601"
"0.0170117182708455","903.956101583985","34.0779991149902","0.000357116030815138"
"0.0171172356977326","908.722369510675","34.2779998779297","0.000364297279236952"
"0.0172133734413078","912.680565643113","34.4780006408691","0.000363936632361509"
"0.0173142010265389","917.034043515835","34.6780014038086","0.000372878075293155"
"0.0174197184534259","921.680332841544","34.8779983520508","0.000373023379604171"
"0.0175158561970012","925.352797685462","35.0779991149902","0.000377137804730231"
"0.0176143394343144","929.216042775038","35.2779998779297","0.00037929570623426"
"0.0177151670195456","933.721222776356","35.4780006408691","0.000387052944095945"
"0.0178136491110387","937.64528044136","35.6780014038086","0.000388794662256718"
"0.017909786854614","941.252651680171","35.8779983520508","0.000389430055307228"
"0.018015304281501","945.736755843073","36.0779991149902","0.000399285970096693"
"0.0181114420250762","949.391218408344","36.2779998779297","0.000401841292139894"
"0.0182099252623895","953.470820151655","36.4780006408691","0.000405100255143117"
"0.0183130971955385","957.671059115897","36.6780014038086","0.00041377160679384"
"0.0184162702745076","961.960321543447","36.8779983520508","0.000414929565422211"
"0.0185124080180828","965.535639944668","37.0779991149902","0.000417931542461866"
"0.018610890109576","969.833574201565","37.2779998779297","0.000423564787933009"
"0.018716407536463","974.367623710712","37.4780006408691","0.000427681934381799"
"0.0188125452800383","978.191461373251","37.6780014038086","0.000430252975644452"
"0.0189110285173515","982.277429776083","37.8779983520508","0.000433798357864978"
"0.0190188902921564","986.926628006574","38.0779991149902","0.000443442224322793"
"0.0191150280357316","990.572638282481","38.2779998779297","0.000443246038438107"
"0.0192135112730449","994.517003395958","38.4780006408691","0.00044792409963112"
"0.0193190286999319","999.241064760821","38.6780014038086","0.000456207877634126"
"0.0194151652976871","1002.92406752395","38.8779983520508","0.000458629210339767"
"0.0195089598391645","1006.65536908344","39.0779991149902","0.000461638348755027"
"0.0196097874243956","1011.01938487537","39.2779998779297","0.000464912744522678"
"0.0197129593575447","1015.55123898468","39.4780006408691","0.000470477169174261"
"0.0198090959552998","1019.25520781623","39.6780014038086","0.000474721537460665"
"0.019912270180089","1023.99880823963","39.8779983520508","0.000478402663555774"
"0.0200154421132381","1028.25305403981","40.0779991149902","0.000486058424725142"
"0.0201115787109932","1031.99719868834","40.2779998779297","0.000488572676279252"
"0.0202124062962243","1036.23410082982","40.4780006408691","0.000495702935706762"
"0.0203179248689315","1040.56946665391","40.6780014038086","0.000500365134452811"
"0.0204093727708508","1044.01975703453","40.8779983520508","0.000505179870499236"
"0.020505509368606","1048.24688964675","41.0779991149902","0.000511226685411539"
"0.0206157166371489","1053.38061262081","41.2779998779297","0.000518866011223895"
"0.02071654422238","1057.31872084476","41.4780006408691","0.000519820980660757"
"0.0208126831117753","1061.15562113632","41.6780014038086","0.000522829653586602"
"0.0209181993928423","1065.81546705601","41.8779983520508","0.00053118873345409"
"0.0210166826301555","1069.58892029233","42.0779991149902","0.000535747951618946"
"0.0211128215195508","1073.49629291859","42.2779998779297","0.000538084636864942"
"0.0212159934526999","1078.01541370886","42.4780006408691","0.000545911411683746"
"0.021316821037931","1082.27668478852","42.6780014038086","0.000552156775734684"
"0.0214106132877683","1086.15507813695","42.8779983520508","0.000555606947466548"
"0.0215137852209173","1090.58594385386","43.0779991149902","0.000562289119622483"
"0.0216169594457065","1095.15182666061","43.2779998779297","0.000567524443258161"
"0.0217130960434617","1098.88214029018","43.4780006408691","0.000570441092507488"
"0.0218139236286928","1103.33045943577","43.6780014038086","0.000575016889256869"
"0.0219194399097597","1107.97976743625","43.8779983520508","0.000583304820857726"
"0.022015578799155","1111.61611795289","44.0779991149902","0.000583133055263852"
"0.0221117176885504","1115.51437966983","44.2779998779297","0.000591617709852564"
"0.0222148896216994","1120.33405069751","44.4780006408691","0.00059654523756476"
"0.0223133728590127","1124.49466269473","44.6780014038086","0.000600801529541546"
"0.0224095094567678","1128.29687566889","44.8779983520508","0.000602776493705758"
"0.0225173723773928","1133.38592225632","45.0779991149902","0.00060880973781129"
"0.0226158556147061","1137.22392024779","45.2779998779297","0.000617813019221282"
"0.0227096478645433","1141.18134799029","45.4780006408691","0.00062071896221408"
"0.0228151641456102","1145.79388304353","45.6780014038086","0.000626473413967329"
"0.0229159917308414","1149.93967609187","45.8779983520508","0.000631517385646855"
"0.0230097862723188","1153.75319537518","46.0779991149902","0.000635864627093817"
"0.0231129582054678","1158.56737790327","46.2779998779297","0.000639719094285433"
"0.0232161301386169","1163.16575262758","46.4780006408691","0.000648651191621916"
"0.0233122690280122","1166.86708697933","46.6780014038086","0.000650663180098004"
"0.0234130966132433","1171.33615265336","46.8779983520508","0.000659010479502622"
"0.0235162685463924","1175.83924702483","47.0779991149902","0.000661310140436743"
"0.0236147517837056","1179.72762944252","47.2779998779297","0.000666629252166993"
"0.0237155793689367","1184.00909820066","47.4780006408691","0.000672643518627174"
"0.0238164069541679","1188.30988647734","47.6780014038086","0.000675073659824809"
"0.023912543551923","1192.30386762709","47.8779983520508","0.000684500393374295"
"0.0240086824413184","1196.38731132011","48.0779991149902","0.000685437244530877"
"0.0241118543744674","1201.12948473361","48.2779998779297","0.000690976998243503"
"0.0242126819596985","1205.43159025019","48.4780006408691","0.000699134449580846"
"0.0243088185574537","1209.27386927135","48.6780014038086","0.000699214155691324"
"0.0244143371301608","1214.06423171122","48.8779983520508","0.000710412255496586"
"0.0245175090633098","1218.33944357983","49.0779991149902","0.000714357457317111"
"0.0246113013131471","1222.11597037592","49.2779998779297","0.000716664279626836"
"0.0247121288983782","1226.51280739539","49.4780006408691","0.00072222652005886"
"0.0248153031231674","1230.91019326481","49.6780014038086","0.000729253691484543"
"0.0249114397209226","1234.77662168414","49.8779983520508","0.000734474620755256"
"0.0250122673061537","1239.43756530375","50.0779991149902","0.000738848574133223"
"0.0251201302267787","1244.32507418633","50.2779998779297","0.00074679734298545"
"0.0252115781286981","1247.455494811","50.4780006408691","0.00074874953397524"
"0.0253147500618471","1252.07999479334","50.6780014038086","0.000755870519421342"
"0.025420266342914","1257.04939208976","50.8779983520508","0.000760713757742673"
"0.0255187495802272","1260.75467816121","51.0779991149902","0.00076723691155331"
"0.0256125441217047","1264.59179799275","51.2779998779297","0.00076983319666497"
"0.0257133717069358","1269.07546307569","51.4780006408691","0.000776505665156961"
"0.0258118526526089","1273.41631739936","51.6780014038086","0.000784471836151907"
"0.0259079915420042","1277.29306419792","51.8779983520508","0.000787894472394571"
"0.0260135078230711","1282.22722532699","52.0779991149902","0.000791004442978342"
"0.0261143354083023","1286.53514865313","52.2779998779297","0.000800915930042498"
"0.0262104742976976","1290.3532782761","52.4780006408691","0.00080014178533965"
"0.0263136462308466","1294.90039041427","52.6780014038086","0.000809430734022506"
"0.0264168181639957","1299.41742557469","52.8779983520508","0.000813578173090102"
"0.0265106127054731","1303.05520310122","53.0779991149902","0.000818759714794991"
"0.0266114402907043","1307.5927652501","53.2779998779297","0.000822020360721481"
"0.0267169565717712","1312.48192068255","53.4780006408691","0.000830276209359629"
"0.0268130954611665","1316.45493576388","53.6780014038086","0.000833666762639585"
"0.0269115764068396","1320.53881853687","53.8779983520508","0.000837819286283861"
"0.0270194393274646","1325.65936911192","54.0779991149902","0.000847642616814325"
"0.0271179225647778","1329.45016600694","54.2779998779297","0.000850289747692777"
"0.027214059162533","1333.34711048399","54.4780006408691","0.00085724774023012"
"0.0273195777352401","1338.29762734183","54.6780014038086","0.00086213788556166"
"0.0274110256371594","1341.77876309013","54.8779983520508","0.000868294878237639"
"0.0275071622349146","1346.04431519946","55.0779991149902","0.000874441128850211"
"0.0276103364597038","1350.57682792872","55.2779998779297","0.000877781194432155"
"0.0277135083928528","1355.39671849638","55.4780006408691","0.000888092644323822"
"0.027809644990608","1359.12812982587","55.6780014038086","0.000891025800543918"
"0.0279128192153972","1363.63001672743","55.8779983520508","0.000894891296253965"
"0.0280159911485462","1368.10292435118","56.0779991149902","0.000902608179764118"
"0.0281121277463014","1371.61666178703","56.2779998779297","0.000905312816488674"
"0.0282106109836146","1375.89176388564","56.4780006408691","0.000911124201177979"
"0.0283161295563217","1380.54184027606","56.6780014038086","0.000919155254235902"
"0.0284146105019948","1384.60794031039","56.8779983520508","0.000927764445146377"
"0.028513093739308","1388.92069351617","57.0779991149902","0.000928420856834287"
"0.0286186123120151","1393.67351461888","57.2779998779297","0.000938377818633531"
"0.0287170932576882","1397.62249007201","57.4780006408691","0.00094294856661311"
"0.0288108877991656","1401.24435094973","57.6780014038086","0.000946775104439869"
"0.0289210927760683","1406.42648249016","57.8779983520508","0.000951997036303166"
"0.0290172316654637","1409.98357907275","58.0779991149902","0.000957340783165497"
"0.029108679567383","1413.51674579714","58.2779998779297","0.000962039218472104"
"0.0292118515005321","1418.29942433759","58.4780006408691","0.000968997067781935"
"0.0293126790857632","1422.76673369176","58.6780014038086","0.000978147443846844"
"0.0294111623230764","1426.71076949526","58.8779983520508","0.000982432452939803"
"0.0295143342562255","1431.37577460456","59.0779991149902","0.000990717376762906"
"0.0296175084810147","1435.77799035362","59.2779998779297","0.000997297606737111"
"0.0297136450787698","1439.27811631049","59.4780006408691","0.000999256242964945"
"0.0298121283160831","1443.58340515684","59.6780014038086","0.00100775543514613"
"0.0299153002492321","1448.103952957","59.8779983520508","0.00101233176899869"
"0.0300114391386274","1451.67180699878","60.0779991149902","0.00101605418042415"
"0.0301099200843005","1455.89180456154","60.2779998779297","0.00102101751501437"
"0.0302154386570076","1460.78557033364","60.4780006408691","0.00102870854595859"
"0.0303139218943208","1464.73004521711","60.6780014038086","0.00103491502374"
"0.0304124028399939","1468.81359868013","60.8779983520508","0.00104027703211012"
"0.030517921412701","1473.298141923","61.0779991149902","0.0010475244874494"
"0.0306164046500142","1477.10496523681","61.2779998779297","0.00105347258279899"
"0.0307125412477694","1480.72539910464","61.4780006408691","0.00105767673996138"
"0.0308157131809184","1485.36812090562","61.6780014038086","0.00106417382636482"
"0.0309165407661495","1489.55376046096","61.8779983520508","0.00107261279137717"
"0.0310079886680689","1492.96980260415","62.0779991149902","0.00107610181357169"
"0.0311088162533","1497.34139252551","62.2779998779297","0.00108233135098254"
"0.0312119904780892","1501.75469504374","62.4780006408691","0.00109043315843144"
"0.0313128180633204","1505.9653621572","62.6780014038086","0.00109565752516244"
"0.0314136456485515","1510.19238499943","62.8779983520508","0.00110218841325873"
"0.0315191619296184","1514.49097787627","63.0779991149902","0.001108414011913"
"0.0316153008190138","1517.85883099309","63.2779998779297","0.00110861846918651"
"0.031709093068851","1521.51384240832","63.4780006408691","0.00111740454607442"
"0.0318146093499179","1526.14569698012","63.6780014038086","0.00112482831448108"
"0.0319107482393133","1529.92529733598","63.8779983520508","0.00112992485065754"
"0.0320092314766265","1533.91291182621","64.0780029296875","0.00113315742399166"
"0.0321170921056113","1538.70821391571","64.2779998779297","0.00114119055384851"
"0.0322179196908425","1542.41602469697","64.4779968261719","0.00114992757531352"
"0.0323117142323199","1545.6546785335","64.6780014038086","0.00115341401941282"
"0.0324148861654689","1550.16073669476","64.8779983520508","0.0011604464186427"
"0.0325157137507001","1554.22771488902","65.0780029296875","0.00116543904325914"
"0.0326095060005373","1557.64167140237","65.2779998779297","0.00117106151086"
"0.0327103335857685","1561.89185571285","65.4779968261719","0.00117789152961529"
"0.0328181965063935","1566.43545521128","65.6780014038086","0.00118378276364258"
"0.0329143331041486","1570.09540627614","65.8779983520508","0.0011925761451336"
"0.0330128163414619","1574.00354729234","66.0780029296875","0.00119356785242732"
"0.033118334914169","1578.38326019309","66.2779998779297","0.00120262054732898"
"0.0332144715119241","1581.9481504451","66.4779968261719","0.00121059216096939"
"0.0333152990971553","1585.76946339783","66.6780014038086","0.00121493668109362"
"0.0334184710303043","1589.88726509826","66.8779983520508","0.00122117968189061"
"0.0335146099196996","1593.14095742366","67.0780029296875","0.00122730136898486"
"0.0336107465174548","1596.66501323874","67.2779998779297","0.00123225704090318"
"0.033713920742244","1600.93352913785","67.4779968261719","0.0012380905542431"
"0.033812401687917","1604.43244762481","67.6780014038086","0.00124383927689587"
"0.0339085405773124","1607.92818278202","67.8779983520508","0.00125110492212918"
"0.0340140568583793","1612.14697287486","68.0780029296875","0.00125574105346803"
"0.0341172310831685","1616.12734254563","68.2779998779297","0.00126496662397678"
"0.0342133676809237","1619.38597452066","68.4779968261719","0.0012677768909915"
"0.0343118509182369","1623.37358901089","68.6780014038086","0.0012768264348879"
"0.0344150228513859","1627.87547591245","68.8779983520508","0.00128533042519075"
"0.0345111617407813","1631.18657794354","69.0780029296875","0.00128793587686318"
"0.0346119893260124","1635.57232819383","69.2779998779297","0.00129329716909574"
"0.0347175056070793","1639.89046012921","69.4779968261719","0.0013025168672765"
"0.0348136444964747","1643.3318591405","69.6780014038086","0.00130937574637548"
"0.0349144720817058","1647.02463143289","69.8779983520508","0.00131523489744006"
"0.0350176440148548","1651.21180776812","70.0780029296875","0.0013210993479226"
"0.0351161272521681","1654.58174651478","70.2779998779297","0.00133064431578332"
"0.0352099195020053","1657.91326576433","70.4779968261719","0.00133483214500932"
"0.0353154357830723","1662.46476870216","70.6780014038086","0.001341604514691"
"0.0354139190203855","1666.31056036305","70.8779983520508","0.00135083266329497"
"0.0355100579097808","1669.74636110476","71.0780029296875","0.00135755920017277"
"0.035610885495012","1673.82321859828","71.2779998779297","0.0013637149754149"
"0.035714057428161","1677.88734277275","71.4779968261719","0.00137132837704757"
"0.0358125406654742","1681.33379120366","71.6780014038086","0.00137958730507723"
"0.0359086772632294","1684.54181921249","71.8779983520508","0.00138276910425831"
"0.0360165401838544","1689.16302609509","72.0780029296875","0.00139090027334719"
"0.0361126767816095","1692.37248111381","72.2779998779297","0.00139583675277889"
"0.0362135043668407","1696.4164076098","72.4779968261719","0.00140191518516448"
"0.0363143319520718","1700.26176019073","72.6780014038086","0.0014116484972036"
"0.0364104708414671","1703.6793391138","72.8779983520508","0.00141908859354664"
"0.0365112984266983","1707.6195329676","73.0780029296875","0.00142588602804293"
"0.0366215056952412","1712.0943066812","73.2779998779297","0.00143297134983852"
"0.0367176422929963","1715.40485986232","73.4779968261719","0.00144158519564314"
"0.0368137811823917","1718.57798101378","73.6780014038086","0.00144928782801584"
"0.0369169531155407","1722.74825277028","73.8779983520508","0.00145392424580971"
"0.037013092004936","1726.2529890668","74.0780029296875","0.00146325193753459"
"0.0371092286026912","1729.72644091568","74.2779998779297","0.00146862282601046"
"0.0372124005358402","1734.03930389146","74.4779968261719","0.00147367102290159"
"0.0373155747606294","1737.90573231079","74.6780014038086","0.00148360012694973"
"0.0374117113583846","1741.28083024707","74.8779983520508","0.00149187967974113"
"0.0375125389436157","1745.17601840424","75.0780029296875","0.00150088496633629"
"0.0376157108767647","1749.21709088045","75.2779998779297","0.0015069954816846"
"0.037714194114078","1752.33082646637","75.4779968261719","0.00151671819488782"
"0.0378103330034733","1755.98474018168","75.6780014038086","0.00152022311533618"
"0.0379158492845402","1760.23602219209","75.8779983520508","0.00153203881217357"
"0.0380143325218535","1763.96490881176","76.0780029296875","0.0015376390078963"
"0.0381104691196086","1767.16635062109","76.2779998779297","0.00154381741308534"
"0.0382159876923157","1771.42674354081","76.4779968261719","0.0015541495593525"
"0.038314470929629","1774.81698973594","76.6780014038086","0.00156183987415916"
"0.038412951875302","1778.3173352328","76.8779983520508","0.00157343557353799"
"0.0385208170875672","1782.68365619456","77.0780029296875","0.00157855624355024"
"0.0386169513936822","1786.09420983817","77.2779998779297","0.00158812670590811"
"0.0387107436435194","1788.87106131941","77.4779968261719","0.00159501022013916"
"0.0388115712287506","1792.90532805613","77.6780014038086","0.00160114093056667"
"0.0389123988139817","1796.81302999236","77.8779983520508","0.00161245332592658"
"0.0390108843429351","1800.28253012154","78.0780029296875","0.00162092294162653"
"0.039114053984444","1804.24094579396","78.2779998779297","0.00162958276346253"
"0.0392172282092332","1808.02405878956","78.4779968261719","0.00163807114196655"
"0.0393133670986285","1811.27050629551","78.6780014038086","0.00164719186993646"
"0.0394141946838597","1814.95197227875","78.8779983520508","0.00165727551647015"
"0.0395150222690908","1818.21400712352","79.0780029296875","0.00166383991980427"
"0.0396111611584861","1821.90140068632","79.2779998779297","0.0016736149110494"
"0.0397096421041592","1825.40602721285","79.4779968261719","0.0016803983092495"
"0.0398151583852261","1829.65017417379","79.6780014038086","0.00168930118817352"
"0.0399159859704572","1833.0766444662","79.8779983520508","0.00170000873374987"
"0.0400121248598526","1836.26623111642","80.0780029296875","0.00170877540330989"
"0.0401176411409195","1840.49281487868","80.2779998779297","0.00171576304394224"
"0.0402184687261506","1843.88426854373","80.4779968261719","0.00172689325390677"
"0.0403122609759879","1846.73872740914","80.6780014038086","0.00173777281572514"
"0.0404154352007771","1850.6726643734","80.8779983520508","0.00174503530995319"
"0.0405162627860082","1854.35654529646","81.0780029296875","0.00175613042917726"
"0.0406124016754036","1857.60266349243","81.2779998779297","0.00176486157831428"
"0.0407132292606347","1861.40092474689","81.4779968261719","0.00177670978779692"
"0.0408163989021436","1865.28348935501","81.6780014038086","0.00178307625070933"
"0.0409125377915389","1868.61610630448","81.8779983520508","0.00179482749516628"
"0.04101336537677","1872.18253333637","82.0780029296875","0.00180408586477531"
"0.0411188816578369","1876.12042202033","82.2779998779297","0.0018138804781896"
"0.0412150205472323","1879.06818537873","82.4779968261719","0.00182495568878949"
"0.0413111594366276","1882.22956114107","82.6780014038086","0.00183317150533801"
"0.0414143290781365","1886.33408067251","82.8779983520508","0.00184422437244601"
"0.0415151566633676","1889.88272496574","83.0780029296875","0.00185400323083397"
"0.0416112955527629","1892.90227789874","83.2779998779297","0.00186566882523869"
"0.0417144697775522","1896.80108846564","83.4779968261719","0.00187714908324277"
"0.0418152973627833","1900.28913972342","83.6780014038086","0.00188370990588909"
"0.0419090896126206","1903.10715495157","83.8779983520508","0.00190035351570402"
"0.0420169525332456","1907.31112609553","84.0780029296875","0.0019064222086188"
"0.0421154334789186","1910.62771662621","84.2779998779297","0.00191859855233164"
"0.0422092257287559","1913.39940891784","84.4779968261719","0.00192808064331455"
"0.0423123999535451","1917.24772528854","84.6780014038086","0.00193993157411992"
"0.042417916234612","1921.23303460894","84.8779983520508","0.00194994016943727"
"0.0425117084844493","1924.15137960955","85.0780029296875","0.00196249721187724"
"0.0426125360696804","1927.75864107837","85.2779998779297","0.00197492520632882"
"0.0427180569340277","1931.47194035922","85.4779968261719","0.00198208300124553"
"0.0428141912401427","1934.37294170113","85.6780014038086","0.0019939991005689"
"0.0429150188253738","1937.71895058959","85.8779983520508","0.00200578013634837"
"0.0430158464106049","1941.00217104277","86.0780029296875","0.00201601073430946"
"0.0431119853000003","1944.29944205489","86.2779998779297","0.00203022978879973"
"0.0432104662456733","1947.52536257238","86.4779968261719","0.00204188320886593"
"0.0433136404704625","1951.46127539649","86.6780014038086","0.00205327008253213"
"0.0434121214161356","1954.5778650022","86.8779983520508","0.00206373371165539"
"0.043510606945089","1957.67579370931","87.0780029296875","0.00207521826648483"
"0.0436137765865978","1961.32279191514","87.2779998779297","0.00208843544452803"
"0.043716950811387","1964.95090968239","87.4779968261719","0.00209962194290481"
"0.0438130897007824","1967.59065844395","87.6780014038086","0.00211429946866128"
"0.0439115706464554","1970.73798364734","87.8779983520508","0.00212584074158551"
"0.0440147448712447","1974.43437834946","88.0780029296875","0.00213416999432361"
"0.04411088376064","1977.53757601617","88.2779998779297","0.00214871102426106"
"0.0442140534021488","1981.02892037371","88.4779968261719","0.0021608068741121"
"0.0443219163227738","1985.04847793153","88.6780014038086","0.00217448982802462"
"0.0444157085726111","1987.51083838642","88.8779983520508","0.00218466972344643"
"0.0445141941015645","1990.54619819824","89.0780029296875","0.00220303550086674"
"0.0446197103826314","1994.37870769012","89.2779998779297","0.00221301845845942"
"0.0447158492720268","1997.19584475834","89.4779968261719","0.00222760073792035"
"0.0448119835781417","1999.95282787108","89.6780014038086","0.00223991658522997"
"0.044915157802931","2003.68303173066","89.8779983520508","0.00225267471909692"
"0.045013638748604","2006.964056784","90.0780029296875","0.00226447351508789"
"0.0451121242775574","2009.99392809623","90.2779998779297","0.00227862697137762"
"0.0452106052232305","2013.16650039773","90.4779968261719","0.00229199568412861"
"0.0453137794480197","2016.62732869755","90.6780014038086","0.00230577345465413"
"0.0454099137541347","2019.44556346569","90.8779983520508","0.00231776431873881"
"0.0455130879789239","2022.91078256519","91.0780029296875","0.00233349069956631"
"0.0456162622037131","2026.19707657814","91.2779998779297","0.00234495778063928"
"0.0457100544535504","2028.74637486649","91.4779968261719","0.00236018415422208"
"0.0458108820387815","2032.07921135594","91.6780014038086","0.00237448928844712"
"0.0459163983198484","2035.61885450984","91.8779983520508","0.00238790497982207"
"0.0460125372092438","2038.44828581714","92.0780029296875","0.00239989140385388"
"0.0461133647944749","2041.61295467923","92.2779998779297","0.00241527131732964"
"0.0462188810755418","2045.35435507796","92.4779968261719","0.00243351277326945"
"0.0463173620212149","2047.97785788074","92.6780014038086","0.00244439262154285"
"0.0464135009106102","2050.621558362","92.8779983520508","0.00245915078438862"
"0.0465166751353994","2054.15900611606","93.0780029296875","0.00247352853496229"
"0.0466104673852367","2056.50698623955","93.2779998779297","0.00248742017135992"
"0.0467089483309097","2059.58537588813","93.4779968261719","0.00250262463113337"
"0.0468121225556989","2063.20580975596","93.6780014038086","0.00251886834973455"
"0.0469152967804882","2066.66839437566","93.8779983520508","0.00253278977745469"
"0.0470044003344896","2068.47828199959","94.0780029296875","0.00254740900961374"
"0.0471099166155565","2072.06336993008","94.2779998779297","0.00256430212175474"
"0.0472130862570654","2075.3806190807","94.4779968261719","0.00257923674089541"
"0.0473139138422965","2078.20895268808","94.6780014038086","0.00259543519960276"
"0.0474123993712499","2080.99074381895","94.8779983520508","0.00260982584065252"
"0.0475155690127588","2084.49152839578","95.0780029296875","0.00262516035100694"
"0.0476140545417122","2087.1369851969","95.2779998779297","0.00264132586738652"
"0.0477125354873853","2089.93436366661","95.4779968261719","0.00265588723563069"
"0.0478180517684522","2093.41363332505","95.6780014038086","0.0026723956386742"
"0.0479165372974056","2096.34427256473","95.8779983520508","0.00268901891018242"
"0.0480150182430786","2098.91376853157","96.0780029296875","0.00270447115355179"
"0.0481205345241456","2102.21411310346","96.2779998779297","0.00272337059668214"
"0.048219020053099","2104.37570378096","96.4779968261719","0.00273787467392147"
"0.0483104656633782","2105.34211878831","96.6780014038086","0.00274920196494264"
"0.0484112932486093","2103.6330000168","96.8779983520508","0.00275832498455273"
"0.0485144674733985","2100.22573947294","97.0780029296875","0.00276408273053876"
"0.0486106063627939","2100.62903442262","97.2779998779297","0.00276897022616133"
"0.0487137760043027","2104.42488073726","97.4779968261719","0.00277999731231716"
"0.0488169502290919","2108.49537157126","97.6780014038086","0.00279160017307158"
"0.0489130891184873","2112.40054879768","97.8779983520508","0.00280072405204676"
"0.0490092234246022","2116.34260874134","98.0780029296875","0.0028162020763683"
"0.0491170863452272","2120.99466099161","98.2779998779297","0.00283035581911305"
"0.0492108785950645","2124.0875402791","98.4779968261719","0.00284289567425158"
"0.0493070174844598","2127.62279263333","98.6780014038086","0.00285800760905222"
"0.0494148804050848","2131.77451326122","98.8779983520508","0.00287702764974775"
"0.0495133613507579","2134.65114566497","99.0780029296875","0.00289241257618643"
"0.0496118468797113","2137.28299098712","99.2779998779297","0.00290897912959986"
"0.0497173631607782","2140.5089115046","99.4779968261719","0.00292980068594247"
"0.0498158441064513","2143.10145916971","99.6780014038086","0.00294604182644843"
"0.0499119829958466","2145.31047048364","99.8779983520508","0.00296518131888904"
"0.0500151572206358","2148.41191183049","100.078002929688","0.0029847940350296"
"0.0501136381663089","2151.05846633153","100.27799987793","0.00300309163615416"
"0.0502097770557042","2153.43103493317","100.477996826172","0.0030195055090397"
"0.050312946697213","2156.65871177052","100.678001403809","0.00303970603088988"
"0.0504161209220023","2159.8462127909","100.877998352051","0.00306158374690663"
"0.0505122598113976","2162.14040561843","101.078002929688","0.00307480851600797"
"0.0506130873966287","2164.9821311648","101.27799987793","0.00306283326372211"
"0.0507209503172538","2168.11013684965","101.477996826172","0.00308649588099454"
"0.0508170846233687","2170.2816068264","101.678001403809","0.00310327555694595"
"0.0509085348169283","2172.17733458389","101.877998352051","0.00312181177510565"
"0.0510117090417175","2175.594474427","102.078002929688","0.00313971750575712"
"0.0511101899873905","2178.06803142105","102.27799987793","0.00315811422032003"
"0.0512086709330636","2180.72226982151","102.477996826172","0.00317580596906844"
"0.0513141917974109","2184.22942105786","102.678001403809","0.00319203651073851"
"0.0514173614389197","2186.99211221017","102.877998352051","0.00321084629344629"
"0.0515135003283151","2189.15897184728","103.078002929688","0.00322656723162834"
"0.051619016609382","2192.2101385379","103.27799987793","0.00324627419147186"
"0.0517175021383354","2194.63100593591","103.477996826172","0.00326376341651817"
"0.0518112943881727","2196.62574622595","103.678001403809","0.00328168977193138"
"0.0519121219734038","2199.55265328592","103.877998352051","0.00329993380596641"
"0.0520152916149126","2202.50414882403","104.078002929688","0.00331754935767839"
"0.0521137771438661","2204.99526901676","104.27799987793","0.00333789940905119"
"0.0522169467853749","2207.77771876759","104.477996826172","0.0033542193246888"
"0.0523154323143283","2210.07937595456","104.678001403809","0.00337404602273243"
"0.0524139132600014","2212.51341575158","104.877998352051","0.00339243557591974"
"0.0525123942056744","2214.87325103417","105.078002929688","0.00341089846159324"
"0.0526179150700217","2218.03045553683","105.27799987793","0.00343410217791693"
"0.0527140493761367","2220.18853357459","105.477996826172","0.00345295435596829"
"0.052810188265532","2222.56746883575","105.678001403809","0.00347216231115969"
"0.0529133624903212","2225.42609896085","105.877998352051","0.00349319928168048"
"0.0530141900755524","2228.17298323435","106.078002929688","0.00351480114150895"
"0.0531103289649477","2230.3578451501","106.27799987793","0.00353426404167187"
"0.0532134986064566","2233.0008870114","106.477996826172","0.00355098069751797"
"0.0533190148875235","2235.8276838389","106.678001403809","0.0035752345579603"
"0.0534128117206411","2237.72077711658","106.877998352051","0.00359382205156932"
"0.0535136393058722","2240.04109520215","107.078002929688","0.00361340898675771"
"0.0536168089473811","2242.9748080016","107.27799987793","0.00363740990741369"
"0.0537106011972183","2244.84397142109","107.477996826172","0.00365622455985689"
"0.0538114287824495","2247.62686025188","107.678001403809","0.00367684273313232"
"0.0539192917030745","2250.74366939757","107.877998352051","0.00369754455127482"
"0.0540177772320279","2252.76826712537","108.078002929688","0.00372005647871511"
"0.0541139115381429","2254.62864894551","108.27799987793","0.00373830566894058"
"0.0542194324024902","2257.60758698157","108.477996826172","0.00376125186219753"
"0.0543179133481632","2259.68289844555","108.678001403809","0.00378610068972509"
"0.0544117055980005","2261.7028858337","108.877998352051","0.00380586751866866"
"0.0545148798227897","2264.48094478485","109.078002929688","0.0038254089075082"
"0.0546157074080208","2266.94835465936","109.27799987793","0.00384652207506542"
"0.0547094996578581","2268.97800180678","109.477996826172","0.00386854215922919"
"0.0548103272430892","2271.55276673322","109.678001403809","0.00389126835502757"
"0.0549158435241561","2274.33785096385","109.877998352051","0.00391140929423273"
"0.0550119824135515","2276.22655344186","110.078002929688","0.00393590549562552"
"0.0551151520550603","2278.77804713005","110.27799987793","0.00395676199948107"
"0.0552183262798495","2281.39189017355","110.477996826172","0.00398029943590793"
"0.0553144651692449","2283.07883540673","110.678001403809","0.00400328487350319"
"0.0554129461149179","2285.40705693171","110.877998352051","0.00402573693184343"
"0.0555161203397071","2288.3003743742","111.078002929688","0.00404705978447835"
"0.0556146012853802","2290.27952732541","111.27799987793","0.00407099138301849"
"0.0557130868143336","2292.47119498065","111.477996826172","0.0040919919737512"
"0.0558232917912363","2295.47757551464","111.678001403809","0.00411755607947414"
"0.0559170840410736","2297.15925178822","111.877998352051","0.00413699806842029"
"0.056015569570027","2298.88637283838","112.078002929688","0.00416287612884973"
"0.0561163971552581","2301.61657207314","112.27799987793","0.00418383604296901"
"0.0562125314613731","2303.53513198891","112.477996826172","0.00420858432478308"
"0.0563086703507684","2305.5518262773","112.678001403809","0.0042316734590971"
"0.0564118445755577","2308.20386927793","112.877998352051","0.00425454947087312"
"0.0565150142170665","2310.8194686413","113.078002929688","0.00427863002602583"
"0.0566088110501841","2312.43045304019","113.27799987793","0.00430178132108009"
"0.056711980691693","2314.8952284349","113.477996826172","0.00432287902006601"
"0.0568151549164822","2317.45791866224","113.678001403809","0.00434764391627148"
"0.0569136358621552","2319.20018797127","113.877998352051","0.00437149416158474"
"0.0570121168078283","2321.29986837342","114.078002929688","0.00439618343366383"
"0.0571152910326175","2323.75344722897","114.27799987793","0.00441895517581106"
"0.0572161186178486","2325.94248040441","114.477996826172","0.00444161663277397"
"0.0573075688114082","2327.31482484124","114.678001403809","0.00446641561712732"
"0.0574177737883109","2330.57894531585","114.877998352051","0.00448969581694247"
"0.057518601373542","2332.66852687877","115.078002929688","0.00451448534828002"
"0.0576123936233793","2333.84679797019","115.27799987793","0.00453984062829033"
"0.0577179099044462","2336.68435225687","115.477996826172","0.00456544140025636"
"0.0578163954333996","2338.53112259804","115.678001403809","0.00458641134030149"
"0.057912534322795","2340.26043904804","115.877998352051","0.00461092759354597"
"0.0580133619080261","2342.55463187557","116.078002929688","0.00463380188659186"
"0.0581141894932572","2344.79745234696","116.27799987793","0.00465880597274252"
"0.0582103237993722","2346.58911815227","116.477996826172","0.00468287249159904"
"0.0583111513846033","2348.90702129802","116.678001403809","0.00470787743711477"
"0.0584166722489506","2351.45917360616","116.877998352051","0.00473188895660665"
"0.0585128065550656","2352.84425136203","117.078002929688","0.00475562576573034"
"0.0586136341402967","2354.63547808737","117.27799987793","0.00477868167126155"
"0.0587168083650859","2357.04690526609","117.477996826172","0.0048049756643861"
"0.0588106006149232","2358.31935901043","117.678001403809","0.00482537670475321"
"0.0589114282001543","2360.28819358242","117.877998352051","0.00485419350727571"
"0.0590146024249435","2362.28051893265","118.078002929688","0.00487444645039532"
"0.0591177720664524","2363.11367317002","118.27799987793","0.00490212946393212"
"0.0592139109558477","2362.21399831765","118.477996826172","0.00491892604072996"
"0.0596805301487563","4.39968718014653","118.636001586914","-0.0439458031676651"