File: MATLAB/ASEN 1022/Data2.csv
"File Path: C:\Users\chts4244\Desktop\Test Run 2 03-19-19 10 29 50 AM\DAQ- Crosshead, … - (Timed).csv   "
"Test: MTS EM Tension (ASEN 1022 Extensometer) 10"
"Test Run: Test Run 2"
"Date: 3/19/2019 10:27:25 AM"
""
""
"Crosshead ","Load ","Time ","Extensometer "
"in","lbf","sec","in"
"0.00365792982661583","371.320981830487","7.31500005722046","0.00016014993216088"
"0.00375641249101902","375.696166719077","7.5149998664856","0.000163163635953088"
"0.00385489515542221","379.6399280976","7.71500015258789","0.000157951139202149"
"0.00395806766148129","384.158692135397","7.91499996185303","0.0001578520794741"
"0.00405889524671242","388.636978488736","8.11499977111816","0.000158897228533261"
"0.00415503299028767","392.802557578083","8.3149995803833","0.000157484879939978"
"0.00425351594114588","397.140420669479","8.51500034332275","0.000160193330097043"
"0.00435668816074993","401.62521089483","8.71500015258789","0.000160688879385437"
"0.0044528261907802","405.700010201001","8.91499996185303","0.000161441217699568"
"0.00455365377601133","410.027225603198","9.11499977111816","0.000161841807147446"
"0.00465917091644332","414.540693238892","9.3149995803833","0.000163216003512195"
"0.00475530866001857","418.42465741441","9.51500034332275","0.00016298232782622"
"0.00485144640359382","422.366854570551","9.71500015258789","0.000161106548714131"
"0.00495461890965289","426.994784865141","9.91499996185303","0.00016295353909629"
"0.00505310157405609","430.941976555906","10.1149997711182","0.000160735374616549"
"0.00515158423845928","435.073060425346","10.3149995803833","0.00016596520189645"
"0.00525475674451835","439.549727671307","10.5150003433228","0.000162742976750079"
"0.00535792925057742","443.74716750076","10.7150001525879","0.000163153484703168"
"0.00545406699415267","447.639199770671","10.914999961853","0.000167809757410904"
"0.00555723950021174","451.917183331568","11.1149997711182","0.00016737506191171"
"0.00565806708544287","455.923239180408","11.3149995803833","0.000167972750319663"
"0.00575420482901812","459.752318360053","11.5150003433228","0.000170465481940081"
"0.00585268749342131","464.047041844691","11.7150001525879","0.000168908777918051"
"0.00595820492030833","468.178345254116","11.914999961853","0.000169479521650291"
"0.00605434266388358","472.10119544921","12.1149997711182","0.000170123168186186"
"0.00615282532828677","475.972947713147","12.3149995803833","0.000172046928514825"
"0.00625834275517378","480.262484565676","12.5150003433228","0.000173979318301069"
"0.00635448049874903","483.853664730704","12.7150001525879","0.000171772236050075"
"0.00645296316315222","487.595174899431","12.914999961853","0.000171352543632773"
"0.00655613566921129","491.99552455863","13.1149997711182","0.00017516173302713"
"0.00665461833361448","495.736321222411","13.3149995803833","0.000177433625727344"
"0.00675075665009978","499.340289591478","13.5150003433228","0.000176866104614125"
"0.0068539285832488","503.733998166176","13.7150001525879","0.000177856290115522"
"0.00695475616847994","507.467275585522","13.914999961853","0.000176573293869096"
"0.00705089448496523","511.136666869671","14.1149997711182","0.000177674480692362"
"0.00715406641811426","515.176476990973","14.3149995803833","0.000178379070534651"
"0.00725723892417333","519.171446070646","14.5150003433228","0.000180916220587257"
"0.00735337666774858","522.389133838753","14.7150001525879","0.000181100769236585"
"0.00745420425297971","526.452215198306","14.914999961853","0.000181731919172049"
"0.00755737675903878","530.46167391689","15.1149997711182","0.000179467456399025"
"0.00765351450261403","534.030461003602","15.3149995803833","0.000180185062041475"
"0.00775434208784516","537.770544162436","15.5150003433228","0.000182344216786235"
"0.00785985951473218","541.838784711601","15.7150001525879","0.000185040241956626"
"0.00795599725830743","545.141050258349","15.914999961853","0.00018340975786243"
"0.00805447992271062","548.606379127839","16.1149997711182","0.000184122565383225"
"0.00815765242876969","552.554311766048","16.3150005340576","0.000184161183101173"
"0.00825613509317288","555.949717150795","16.5149993896484","0.000186343451185696"
"0.00835227283674813","559.419217279971","16.7150001525879","0.000184260171215466"
"0.0084554453428072","563.359191593778","16.9150009155273","0.000185086755091178"
"0.00855627292803833","566.827758678024","17.1149997711182","0.000187337056243944"
"0.00865006632369569","570.099398397075","17.3150005340576","0.000186490939716271"
"0.00875323825684471","573.947550112785","17.5149993896484","0.000188920543810736"
"0.00885406584207585","577.620893116637","17.7150001525879","0.000189509352112939"
"0.00895020415856114","580.735232437513","17.9150009155273","0.000188117735702031"
"0.00905337609171017","584.446830283489","18.1149997711182","0.000188708119506867"
"0.00915654859776924","588.143554295583","18.3150005340576","0.000188412157756572"
"0.00925268634134449","591.320682051739","18.5149993896484","0.000190776629139913"
"0.00935351392657562","594.995726490463","18.7150001525879","0.000191373744637817"
"0.00945668643263469","598.961551637327","18.9150009155273","0.000189279328728522"
"0.00955516909703788","602.276221193142","19.1149997711182","0.00019068217059569"
"0.00965365233435112","605.548793957123","19.3150005340576","0.000192065515617774"
"0.00975916861541804","609.356001465911","19.5149993896484","0.000191732422134969"
"0.00985765185273128","612.586587208048","19.7150001525879","0.000190337887463503"
"0.00995378959630653","615.658555312109","19.9150009155273","0.000194030561276774"
"0.0100546171815377","619.479374299874","20.1149997711182","0.000195199405196064"
"0.0101554447667688","622.962376138035","20.3150005340576","0.000195631630020674"
"0.010251582510344","626.061951395021","20.5149993896484","0.000195435730591013"
"0.0103547555893132","629.886831872481","20.7150001525879","0.000195940195792034"
"0.0104555831745443","633.420876756805","20.9150009155273","0.000196856189442168"
"0.0105517209181195","636.23845290499","21.1149997711182","0.000197020829467316"
"0.0106525485033507","639.775351809099","21.3150005340576","0.000197830566206918"
"0.0107557204364997","643.517904792748","21.5149993896484","0.000199479096967637"
"0.0108542036738129","646.507710057986","21.7150001525879","0.000199944926547272"
"0.0109503414173882","649.970349562677","21.9150009155273","0.000198886707977632"
"0.0110558588442752","653.960598532706","22.1149997711182","0.000202380832652268"
"0.0111543409357683","657.069010274027","22.3150005340576","0.000202537720488324"
"0.0112528241730816","660.227751556565","22.5149993896484","0.000200969343424058"
"0.0113583415999686","664.221787591308","22.7150001525879","0.000202550521447217"
"0.0114568236914617","667.279211171463","22.9150009155273","0.000205452794235018"
"0.011555306928775","670.541739981198","23.1149997711182","0.000206349380557264"
"0.011658478861924","674.388354917024","23.3150005340576","0.000209718682455113"
"0.0117593064471551","677.60604268513","23.5149993896484","0.000208651565876285"
"0.0118530998428125","680.652763691089","23.7150001525879","0.000206029428198693"
"0.0119539274280436","684.342901503679","23.9150009155273","0.00021015097889348"
"0.0120570993611926","687.929910409021","24.1149997711182","0.000211588034232598"
"0.01215089275685","690.849627534527","24.3150005340576","0.00021103553410471"
"0.0122517203420811","694.439325804667","24.5149993896484","0.000215141401386922"
"0.0123572377689681","698.121999257818","24.7150001525879","0.000215509621417067"
"0.0124533755125434","700.956809294708","24.9150009155273","0.00021441532741782"
"0.0125518576040365","704.14222468524","25.1149997711182","0.000218744665425771"
"0.0126550306830057","707.758377523391","25.3150005340576","0.000219093227479882"
"0.0127511684265809","710.785888780794","25.5149993896484","0.000218295235396271"
"0.012849650518074","714.142655128445","25.7150001525879","0.0002196143965895"
"0.012957513438699","717.845471375082","25.9150009155273","0.000222676027887941"
"0.0130559955301922","720.949711856716","26.1149997711182","0.00022307260696548"
"0.0131521332737674","723.834137929876","26.3150005340576","0.000226881599422007"
"0.0132576507006545","727.5544076052","26.5149993896484","0.000230157534885413"
"0.0133584782858856","730.514245662691","26.7150001525879","0.000226632079192507"
"0.0134546160294608","733.457508451427","26.9150009155273","0.000230393538018459"
"0.013555443614692","737.142651729392","27.1149997711182","0.000231688923444681"
"0.0136562711999231","740.502436751816","27.3150005340576","0.000233806953990033"
"0.0137524089434983","743.205248373629","27.5149993896484","0.000235604316039253"
"0.0138532365287295","746.657679269088","27.7150001525879","0.000233723899936459"
"0.0139587539556165","750.136784272542","27.9150009155273","0.000238335073881326"
"0.0140525473512738","752.818849365915","28.1149997711182","0.00023451120366698"
"0.014153374936505","756.144001955942","28.3150005340576","0.000241027751108622"
"0.014258892363392","759.769869438363","28.5149993896484","0.000243145513102388"
"0.0143550301069672","762.337444430343","28.7150001525879","0.000244946813908191"
"0.0144511678505425","765.386909686095","28.9150009155273","0.000246114118131726"
"0.0145543397836915","769.033029731994","29.1149997711182","0.000249461631544299"
"0.0146528230210048","772.099893531439","29.3150005340576","0.000251660012723933"
"0.0147513051124979","775.17597801019","29.5149993896484","0.00025529100918981"
"0.0148568225393849","778.692569465826","29.7150001525879","0.000252556599046179"
"0.014957650124616","781.807677176644","29.9150009155273","0.000255780847281159"
"0.0150537878681913","784.508677593593","30.1149997711182","0.00025897593081399"
"0.0151569609471604","787.827463524099","30.3150005340576","0.000261188957006735"
"0.0152577885323915","790.984174061789","30.5149993896484","0.000260328535631292"
"0.0153539262759668","793.803561414838","30.7150001525879","0.000264110046308937"
"0.0154547538611979","797.122402230341","30.9150009155273","0.000264848634781908"
"0.0155602701422648","800.415282442794","31.1149997711182","0.000265843725825594"
"0.0156540635379222","802.969355725789","31.3150005340576","0.000267456968908022"
"0.0157548911231533","806.056033008744","31.5149993896484","0.000269681865080832"
"0.0158580642021224","809.382777263652","31.7150001525879","0.000270697348141551"
"0.0159542019456977","811.89596122472","31.9150009155273","0.000274290693675188"
"0.0160526840371908","814.826820004389","32.1150016784668","0.000276478046336391"
"0.01615585711616","818.299064383359","32.314998626709","0.000279392833628061"
"0.0162543392076531","821.115268406647","32.5149993896484","0.000278034983103129"
"0.0163504769512284","823.678233058973","32.7150001525879","0.000280085034290554"
"0.0164536500301975","827.237360386411","32.9150009155273","0.000283943905728167"
"0.0165544776154286","830.163114861464","33.1150016784668","0.000287337019199901"
"0.0166506153590039","832.706320915276","33.314998626709","0.000285854793484158"
"0.0167537872921529","835.832186085285","33.5149993896484","0.000288014932918064"
"0.016856960371122","838.594273502642","33.7150001525879","0.000288804922164436"
"0.0169530981146972","841.145382995859","33.9150009155273","0.000293493779131173"
"0.0170539256999284","844.203959160926","34.1150016784668","0.000293871112011775"
"0.0171570976330774","847.327189851134","34.314998626709","0.000296320588923542"
"0.0172532353766527","849.79410576068","34.5149993896484","0.000296923827397588"
"0.0173540629618838","852.649113476052","34.7150001525879","0.000297234040285336"
"0.0174595803887708","855.878436863283","34.9150009155273","0.000299463430221337"
"0.017555718132346","857.897875401469","35.1150016784668","0.000300085449402906"
"0.0176542013696593","860.487184851815","35.314998626709","0.000301130902820531"
"0.0177573733028083","863.68374189651","35.5149993896484","0.000304920559562926"
"0.0178558565401215","866.088637760719","35.7150001525879","0.000305792421235897"
"0.0179519942836968","868.649297243218","35.9150009155273","0.000307644138125956"
"0.0180551662168458","871.746018480418","36.1150016784668","0.000310163259415477"
"0.018155993802077","874.644056032555","36.314998626709","0.000310883443153144"
"0.0182521315456522","877.065691820505","36.5149993896484","0.000314300529329715"
"0.0183529591308833","880.214992883753","36.7150001525879","0.000316217772806555"
"0.0184561322098525","883.117311465567","36.9150009155273","0.000317217787295969"
"0.0185522699534277","885.318419340096","37.1150016784668","0.000318564627205909"
"0.0186530975386588","888.420080226925","37.314998626709","0.000321109601061362"
"0.0187586149655459","891.737274492551","37.5149993896484","0.000325192838396664"
"0.0188547527091211","894.265167632513","37.7150001525879","0.00032919543864266"
"0.0189532348006142","897.121273047802","37.9150009155273","0.000330765140561413"
"0.0190587522275013","900.344174890516","38.1150016784668","0.000333262813530998"
"0.0191548899710765","902.727665606335","38.314998626709","0.000335828949251363"
"0.0192533732083897","905.358358343569","38.5149993896484","0.000337177543698326"
"0.0193588894894567","908.639822476881","38.7150001525879","0.000339214310534005"
"0.0194573727267699","910.890765927663","38.9150009155273","0.000339547529340883"
"0.0195558559640831","913.34105168346","39.1150016784668","0.000341664825845235"
"0.0196566835493143","916.247980604928","39.314998626709","0.000343491191465653"
"0.0197551667866275","918.816763066817","39.5149993896484","0.000344961815752918"
"0.0198513033843827","921.143667351889","39.7150001525879","0.00034621699005512"
"0.0199544753175317","924.044229613836","39.9150009155273","0.000346208432211273"
"0.0200576495423209","926.691113424853","40.1150016784668","0.000349550216523362"
"0.0201514417921582","928.714613452734","40.314998626709","0.00035143598575442"
"0.0202522693773893","931.249092792201","40.5149993896484","0.00035139813788435"
"0.0203554413105383","934.027700593316","40.7150001525879","0.000354659034458986"
"0.0204515801999337","936.151310853671","40.9150009155273","0.000356392338003424"
"0.0205524077851648","938.565482282183","41.1150016784668","0.00035671599637387"
"0.0206579240662317","941.52575941964","41.314998626709","0.000360119762391816"
"0.0207540629556271","943.570225515945","41.5149993896484","0.000359027330350226"
"0.0208525439013001","945.572539935418","41.7150001525879","0.000361768955579779"
"0.0209580624740072","948.574968749707","41.9150009155273","0.000364512657608258"
"0.0210565457113205","950.781894433799","42.1150016784668","0.000364737202540337"
"0.0211550266569935","952.853363948073","42.314998626709","0.000367245474345817"
"0.0212605452297006","955.933948996487","42.5149993896484","0.000370222350763978"
"0.0213590284670138","958.031543768797","42.7150001525879","0.000369837570052748"
"0.0214528207168511","960.209270635084","42.9150009155273","0.000370312476675961"
"0.0215536483020822","963.046166301817","43.1150016784668","0.000373850697520882"
"0.0216568202352313","965.782183346133","43.314998626709","0.000375329199321311"
"0.0217529591246266","967.972533761471","43.5149993896484","0.000377376278537861"
"0.0218537867098577","970.753666272396","43.7150001525879","0.000377675409196861"
"0.0219593029909247","973.461582198825","43.9150009155273","0.000381967543858547"
"0.02205544188032","975.406706452598","44.1150016784668","0.000382888819023189"
"0.022153922825993","977.70913202951","44.314998626709","0.000384284678549143"
"0.0222570970507823","980.661286187579","44.5149993896484","0.000385389284929261"
"0.0223532336485374","982.779407948346","44.7150001525879","0.000387989508797503"
"0.0224517168858507","985.501593973702","44.9150009155273","0.000387998174061984"
"0.0225572331669176","988.719830591768","45.1150016784668","0.00039167518236612"
"0.0226557164042308","990.800630555341","45.314998626709","0.000392290165496158"
"0.0227518552936262","993.016776918739","45.5149993896484","0.000394963650236834"
"0.0228573715746931","995.870028314243","45.7150001525879","0.000394358943680789"
"0.0229581991599242","998.365209996664","45.9150009155273","0.00039509155240513"
"0.0230543380493196","1000.27948888276","46.1150016784668","0.000395277103647043"
"0.0231551656345507","1003.13372820819","46.314998626709","0.00040007930728616"
"0.0232583375676997","1005.67040294749","46.5149993896484","0.000403144626693037"
"0.0233544741654549","1007.90301480965","46.7150001525879","0.000406337848268211"
"0.0234529574027681","1010.39786718209","46.9150009155273","0.000404861781335487"
"0.0235561293359171","1013.10896643828","47.1150016784668","0.000408021917355368"
"0.0236522682253125","1015.11391533756","47.314998626709","0.000408908961144621"
"0.0237530958105436","1017.63028262839","47.5149993896484","0.000409768039762138"
"0.0238586120916105","1020.51920927121","47.7150001525879","0.000412386775786317"
"0.0239547509810059","1022.40483818946","47.9150009155273","0.000414176152901739"
"0.024050887578761","1024.46489162459","48.1150016784668","0.000415135061095183"
"0.0241540618035502","1027.359306767","48.314998626709","0.000416912228065198"
"0.0242525427492233","1029.74669431752","48.5149993896484","0.000417687482781265"
"0.0243510259865365","1031.73759265785","48.7150001525879","0.000418773541198567"
"0.0244565445592436","1034.54353318691","48.9150009155273","0.000421277695213074"
"0.0245573721444748","1036.77131516944","49.1150016784668","0.000425154505896576"
"0.0246535087422299","1038.64486938859","49.314998626709","0.000425505520721832"
"0.0247566806753789","1041.18209297785","49.5149993896484","0.000429152809317209"
"0.0248575082606101","1043.66080916151","49.7150001525879","0.000430348759043162"
"0.0249513028020875","1045.609665595","49.9150009155273","0.000428751808090234"
"0.0250544747352365","1048.22372817849","50.1150016784668","0.000433503667258852"
"0.0251599910163035","1050.8787349689","50.314998626709","0.00043300537874429"
"0.0252561299056988","1052.70739326142","50.5149993896484","0.00043511383094977"
"0.025354613143012","1054.96700854155","50.7150001525879","0.000435988306524837"
"0.0254577850761611","1057.64912851992","50.9150009155273","0.000438573097628651"
"0.0255562683134743","1059.43892823537","51.1150016784668","0.000441371011270456"
"0.0256524049112295","1061.62587578097","51.314998626709","0.000441362095357828"
"0.0257579234839366","1064.52687712288","51.5149993896484","0.000443987634688832"
"0.0258564044296096","1066.57847826865","51.7150001525879","0.000447140680946864"
"0.025952543319005","1068.67332879116","51.9150009155273","0.000447630196776311"
"0.026055715252154","1071.41033376541","52.1150016784668","0.000449687158691195"
"0.0261565428373851","1073.60342843054","52.314998626709","0.000454480482224562"
"0.0262526817267805","1075.60947502973","52.5149993896484","0.00045294698105949"
"0.0263535093120116","1078.28775305839","52.7150001525879","0.000454931648887646"
"0.0264590255930785","1080.73979513405","52.9150009155273","0.000458914018247559"
"0.0265528178429158","1082.60917809352","53.1150016784668","0.000457754806378457"
"0.0266536454281469","1085.02598400183","53.314998626709","0.000462348685601239"
"0.0267568196529361","1087.86430667846","53.5149993896484","0.000465108930407363"
"0.0268553005986092","1089.72150516884","53.7150001525879","0.000466692990884203"
"0.0269537838359224","1092.24423911919","53.9150009155273","0.000467150065682161"
"0.0270593024086295","1094.95566768536","54.1150016784668","0.00046813568580661"
"0.0271577833543026","1096.82186731506","54.314998626709","0.000471833497906877"
"0.0272539222436979","1098.78828694724","54.5149993896484","0.000471882231067866"
"0.0273570941768469","1101.49916666344","54.7150001525879","0.000475516521766521"
"0.0274555774141602","1103.57667352726","54.9150009155273","0.000477233819636483"
"0.0275517140119153","1105.63376317262","55.1150016784668","0.000477889479379954"
"0.0276548882367045","1108.7200562606","55.314998626709","0.000483209915964692"
"0.0277580601698536","1111.02775079712","55.5149993896484","0.000484263497543628"
"0.0278518524196908","1112.72194084976","55.7150001525879","0.000483450860446906"
"0.027952680004922","1115.26289661874","55.9150009155273","0.00048651893698339"
"0.028055851938071","1117.82152535639","56.1150016784668","0.000489012492162003"
"0.0281519908274663","1119.70550772476","56.314998626709","0.00049081407942283"
"0.0282528184126975","1122.00123733217","56.5149993896484","0.000488832061303648"
"0.0283559903458465","1124.65185332291","56.7150001525879","0.000494467526801227"
"0.0284544735831597","1126.8507657976","56.9150009155273","0.000495263800154693"
"0.028552956820473","1129.29797799363","57.1150016784668","0.000497169155748029"
"0.0286584731015399","1131.94255663482","57.314998626709","0.00049999918815942"
"0.0287569563388531","1133.89942627771","57.5149993896484","0.000502087337865062"
"0.0288530929366083","1135.92742687525","57.7150001525879","0.00050192910727108"
"0.0289586115093154","1138.82315925756","57.9150009155273","0.000505605757506436"
"0.0290594390945465","1140.85412364488","58.1150016784668","0.000507547313853453"
"0.0291532313443838","1142.69310031664","58.314998626709","0.000510535684279459"
"0.0292540589296149","1145.50892014495","58.5149993896484","0.000511932510591119"
"0.0293572308627639","1147.90454044486","58.7150001525879","0.000514262893826583"
"0.0294533697521593","1150.03824954446","58.9150009155273","0.000516072107952429"
"0.0295541973373904","1152.70489195399","59.1150016784668","0.000517834271840553"
"0.0296573692705394","1155.28745054984","59.314998626709","0.000520207014612718"
"0.0297535081599348","1157.08098244501","59.5149993896484","0.000523540026239691"
"0.0298543357451659","1159.38296894196","59.7150001525879","0.000526120269869997"
"0.0299575076783149","1162.01986368372","59.9150009155273","0.000525933608614865"
"0.0300512999281522","1163.87014666463","60.1150016784668","0.000528010407540174"
"0.0301497831654654","1166.35435134787","60.314998626709","0.000531193388348233"
"0.0302576460860904","1169.42922835672","60.5149993896484","0.000534120314171552"
"0.0303561270317635","1171.3210043945","60.7150001525879","0.000537957164379181"
"0.0304522659211588","1173.45811636384","60.9150009155273","0.000538738363037"
"0.0305554378543078","1175.99599857305","61.1150016784668","0.000540809647703092"
"0.030656265439539","1178.21104723653","61.314998626709","0.000542940550821093"
"0.0307547486768522","1180.2865782405","61.5149993896484","0.000542140840007337"
"0.0308602649579191","1183.05245272257","61.7150001525879","0.000549787935912224"
"0.0309587481952324","1185.27902723519","61.9150009155273","0.000551244094220767"
"0.0310525404450696","1187.08452405946","62.1150016784668","0.000554182442438176"
"0.0311533680303008","1189.75555726866","62.314998626709","0.000555068698476113"
"0.03125654225509","1192.28520672849","62.5149993896484","0.000559263939725869"
"0.0313526788528451","1194.22912351235","62.7150001525879","0.000559586165821194"
"0.0314535064380763","1196.67765294828","62.9150009155273","0.000562496477253112"
"0.0315590250107834","1199.47865382771","63.1150016784668","0.000565637886275787"
"0.0316551616085385","1201.37141779542","63.314998626709","0.000569193652490939"
"0.0317513004979339","1203.42356779115","63.5149993896484","0.000567823108427747"
"0.0318544724310829","1206.06529241255","63.7150001525879","0.000572992404180352"
"0.0319529556683961","1208.39746565723","63.9150009155273","0.00057845080466611"
"0.0320514366140692","1210.68364527536","64.1149978637695","0.000579871514165411"
"0.0321569551867763","1213.6934286791","64.3150024414063","0.000583993172280831"
"0.0322577827720074","1215.78531541184","64.5149993896484","0.000584545564988085"
"0.0323539193697626","1217.80299763016","64.7149963378906","0.000585818034012373"
"0.0324570935945518","1220.32726836039","64.9150009155273","0.000588309190130158"
"0.0325579211797829","1222.64714736599","65.1149978637695","0.000590900140016992"
"0.0326540577775381","1224.5771233609","65.3150024414063","0.000591477167856326"
"0.0327548853627692","1227.31281109525","65.5149993896484","0.000598972299370885"
"0.0328580572959182","1230.04421779991","65.7149963378906","0.000598183903530585"
"0.0329541961853136","1231.85586174372","65.9150009155273","0.000604018562690604"
"0.0330550237705447","1234.34138366686","66.1149978637695","0.000605489437626015"
"0.0331581957036937","1237.08212082083","66.3150024414063","0.000606864135287057"
"0.0332543345930891","1238.9673106591","66.5149993896484","0.000608441714718975"
"0.0333528155387621","1241.39564241655","66.7149963378906","0.00061284051807029"
"0.0334606784593871","1244.1418680701","66.9150009155273","0.000616105389208386"
"0.0335568173487825","1246.21311804439","67.1149978637695","0.00061621868217045"
"0.0336506095986197","1248.32487314564","67.3150024414063","0.000617039304200971"
"0.0337561258796866","1251.24826756587","67.5149993896484","0.00062254948143235"
"0.0338546091169999","1253.49580814691","67.7149963378906","0.000624219943905858"
"0.0339507480063952","1255.53302942376","67.9150009155273","0.000627127247560021"
"0.0340539199395443","1258.27914530731","68.1149978637695","0.00063246576661816"
"0.0341570918726933","1260.78343789905","68.3150024414063","0.000635424703790432"
"0.0342532307620886","1262.69091104565","68.5149993896484","0.000636936326953033"
"0.0343564026952377","1265.21199844613","68.7149963378906","0.000642001639531859"
"0.0344572302804688","1267.61354632559","68.9150009155273","0.000643381206928312"
"0.0345533668782239","1269.54977921003","69.1149978637695","0.000645339914769902"
"0.0346541944634551","1272.13058148602","69.3150024414063","0.000647823264988279"
"0.0347597130361622","1275.07900346436","69.5149993896484","0.000652970145635241"
"0.0348535052859994","1276.85991181048","69.7149963378906","0.000655995253918099"
"0.0349543328712306","1279.2767177188","69.9150009155273","0.000657288813193541"
"0.0350598514439377","1281.77914422067","70.1149978637695","0.000659432857435776"
"0.0351559880416928","1283.70143631616","70.3150024414063","0.000660551893987737"
"0.0352521269310882","1285.77751617009","70.5149993896484","0.000661954879082417"
"0.0353552988642372","1288.65568535372","70.7149963378906","0.000666848390260491"
"0.0354561264494683","1290.95086611118","70.9150009155273","0.000671134043877255"
"0.0355499186993056","1293.02771435505","71.1149978637695","0.000678389949639746"
"0.0356530906324546","1295.85264509268","71.3150024414063","0.000678201104165055"
"0.0357539182176857","1298.2732929507","71.5149993896484","0.00068099919684125"
"0.0358500571070811","1300.198219526","71.7149963378906","0.000683673970629534"
"0.0359532290402301","1302.94378655959","71.9150009155273","0.000684923559058766"
"0.0360587476129372","1305.44840846131","72.1149978637695","0.000686604835209437"
"0.0361548842106924","1307.20132545953","72.3150024414063","0.000689207852014164"
"0.0362533674480056","1309.71297264071","72.5149993896484","0.000695582478894764"
"0.0363565393811546","1312.4838965424","72.7149963378906","0.000698835462149357"
"0.03645267827055","1314.56546489592","72.9150009155273","0.000699699553729798"
"0.0365535058557811","1316.92145822881","73.1149978637695","0.000704084893694976"
"0.0366613664847659","1319.94551173147","73.3150024414063","0.000706939704465959"
"0.0367575053741613","1321.7089666489","73.5149993896484","0.000709725407962357"
"0.0368559886114745","1323.69042476994","73.7149963378906","0.000712957909682722"
"0.0369591605446235","1326.47693601046","73.9150009155273","0.000714480274908729"
"0.0370552971423787","1328.68473985449","74.1149978637695","0.000719894776162031"
"0.037151436031774","1330.82196159382","74.3150024414063","0.000717185126474552"
"0.037256952312841","1333.8204386884","74.5149993896484","0.000724105951472508"
"0.0373577798980721","1336.33922091905","74.7149963378906","0.000727270133669605"
"0.0374539187874674","1338.16963553145","74.9150009155273","0.000729464737223608"
"0.0375524020247807","1340.75856078682","75.1149978637695","0.000731939207336235"
"0.0376555739579297","1343.14276500759","75.3150024414063","0.000737305798986743"
"0.0377517105556848","1345.12839438831","75.5149993896484","0.000738583245167076"
"0.037852538140916","1347.68043692646","75.7149963378906","0.000741969859690449"
"0.0379557123657052","1350.43182176962","75.9150009155273","0.000743989510838434"
"0.0380541933113782","1352.60845093599","76.1149978637695","0.000747624768322796"
"0.0381526765486915","1354.8551133571","76.3150024414063","0.000751789967601892"
"0.0382558484818405","1357.54810056465","76.5149993896484","0.000754339130862073"
"0.0383543317191537","1359.70584929244","76.7149963378906","0.000757727177660568"
"0.038452814956467","1361.93165541511","76.9150009155273","0.000761143726733968"
"0.038560677877092","1364.80521425909","77.1149978637695","0.00076135935575342"
"0.038659158822765","1366.70862591599","77.3150024414063","0.000766377904549549"
"0.0387529510726023","1368.60490252344","77.5149993896484","0.000767402769012311"
"0.0388537786578334","1371.32335636908","77.7149963378906","0.000770188687349978"
"0.0389546062430646","1373.72215999874","77.9150009155273","0.000774935461941916"
"0.0390507451324599","1375.95060060122","78.1149978637695","0.00077787642406142"
"0.0391539193572491","1378.70868141388","78.3150024414063","0.000781604278132349"
"0.0392570889987579","1381.39036231228","78.5149993896484","0.000784325457634551"
"0.0393532278881533","1383.10288395354","78.7149963378906","0.000785527064847232"
"0.0394517088338263","1385.46809796573","78.9150009155273","0.000789669490951905"
"0.0395572296981736","1388.16229264319","79.1149978637695","0.000794579974590163"
"0.0396533640042886","1390.29106209316","79.3150024414063","0.000795547261593064"
"0.039751849533242","1392.50896477642","79.5149993896484","0.000795350252150184"
"0.039857365814309","1395.59459924446","79.7149963378906","0.00080030040980929"
"0.039955846759982","1397.88802368204","79.9150009155273","0.000805977733547279"
"0.0400519856493773","1399.88978925156","80.1149978637695","0.000808763078974897"
"0.0401575019304443","1402.70615792983","80.3150024414063","0.00081291710650805"
"0.0402559874593977","1404.82790210033","80.5149993896484","0.000816093821112455"
"0.0403544684050707","1406.97730830875","80.7149963378906","0.000817551662344266"
"0.0404599846861377","1409.85668496229","80.9150009155273","0.000821136288903104"
"0.0405584702150911","1411.98446648233","81.1149978637695","0.00082584489336307"
"0.0406522624649283","1414.01027168003","81.3150024414063","0.000827522875280963"
"0.0407530900501595","1416.6365187326","81.5149993896484","0.000832706207329752"
"0.0408562642749487","1419.39800241501","81.7149963378906","0.000835124317416371"
"0.0409523985810637","1421.37891168609","81.9150009155273","0.000833910965547699"
"0.0410532261662948","1423.97145935119","82.1149978637695","0.000839162115823463"
"0.0411587470306421","1426.81516075741","82.3150024414063","0.000844800696519431"
"0.041254881336757","1428.47707843247","82.5149993896484","0.000847377359461934"
"0.0413510202261524","1430.69212709596","82.7149963378906","0.000851966154108037"
"0.0414541944509416","1433.62825483523","82.9150009155273","0.000852395048892991"
"0.0415526753966147","1435.70631054901","83.1149978637695","0.00085970838888783"
"0.0416511563422877","1438.1061021086","83.3150024414063","0.000861408857525121"
"0.041756677206635","1441.03202123864","83.5149993896484","0.000865092024612277"
"0.0418551581523081","1443.23784922282","83.7149963378906","0.000871096551601636"
"0.0419536390979811","1445.34521352439","83.9150009155273","0.000873560709333392"
"0.0420568133227703","1448.20318502954","84.1149978637695","0.000877838628664503"
"0.0421576409080014","1450.33129585956","84.3150024414063","0.000878631751012702"
"0.0422537797973968","1452.19222652966","84.5149993896484","0.000884501071230648"
"0.0423546073826279","1454.82066898206","84.7149963378906","0.000887871930727691"
"0.0424554349678591","1457.31914376424","84.9150009155273","0.000888950791962511"
"0.0425539159135321","1459.60740901221","85.1149978637695","0.000897389398906087"
"0.0426524014424855","1461.79995482739","85.3150024414063","0.000898067724403346"
"0.0427555710839944","1464.72993544712","85.5149993896484","0.000900194223275349"
"0.0428540566129478","1466.9197370125","85.7149963378906","0.000900412000707483"
"0.0429548841981789","1469.26409472626","85.9150009155273","0.000905113443791844"
"0.0430604004792458","1472.0490691869","86.1149978637695","0.000909255010531445"
"0.0431565393686412","1473.97948426177","86.3150024414063","0.000912745035318548"
"0.0432503316184785","1476.10287498215","86.5149993896484","0.000914245844803985"
"0.0433535012599873","1479.08367910806","86.7149963378906","0.000916437225738966"
"0.0434543288452184","1481.32968290921","86.9150009155273","0.000922934240528646"
"0.0435504677346138","1483.35109730725","87.1149978637695","0.000923369938620425"
"0.0436559840156807","1486.23727970028","87.3150024414063","0.000928453369479531"
"0.0437568116009118","1488.69909130521","87.5149993896484","0.000928813443444926"
"0.0438552971298652","1490.69075803548","87.7149963378906","0.000929231811007742"
"0.0439561247150964","1493.11535761321","87.9150009155273","0.000933043453173243"
"0.0440569523003275","1495.6216260648","88.1149978637695","0.000935068045670394"
"0.0441530866064425","1497.95325045952","88.3150024414063","0.00093463571342515"
"0.0442539141916736","1500.53591882536","88.5149993896484","0.000932968545184419"
"0.0443594350560209","1503.47435173446","88.7149963378906","0.000930679411472437"
"0.0444579160016939","1505.41354840868","88.9150009155273","0.000914383128374324"
"0.0445540548910893","1507.47316276385","89.1149978637695","0.000901000450940905"
"0.0446595711721562","1510.35671067707","89.3150024414063","0.000895419089636017"
"0.0447557100615516","1512.33344868847","89.5149993896484","0.000892604597409689"
"0.0448518489509469","1514.27637754241","89.7149963378906","0.000890721585308238"
"0.0449550185924557","1517.02787215556","89.9150009155273","0.000893154591056115"
"0.0450558461776869","1519.64423990887","90.1149978637695","0.000896112955318339"
"0.0451519850670822","1521.62306355011","90.3150024414063","0.000897882316388945"
"0.0452551592918714","1524.44645750786","90.5149993896484","0.00090532520566847"
"0.0453559868771026","1526.80826865031","90.7149963378906","0.000907552393481473"
"0.0454497791269398","1528.66568668067","90.9150009155273","0.000912063272360998"
"0.0455529487684486","1531.308399232","91.1149978637695","0.000912236506036871"
"0.0456584696327959","1534.09282484268","91.3150024414063","0.000917706436337353"
"0.0457522618826332","1535.93970495384","91.5149993896484","0.000920777090969056"
"0.0458507428283063","1538.50294403114","91.7149963378906","0.000924354699379801"
"0.0459562591093732","1541.58770033924","91.9150009155273","0.000929603701242884"
"0.0460547446383266","1543.44215457983","92.1149978637695","0.000930842619222464"
"0.0461532255839996","1545.99518504791","92.3150024414063","0.000938137769323268"
"0.0462587418650666","1548.79585661736","92.5149993896484","0.00094051255308748"
"0.04635722739402","1550.54021155623","92.7149963378906","0.000943796688325953"
"0.046453361700135","1552.51541278774","92.9150009155273","0.000946545224282964"
"0.0465565359249242","1555.28062864986","93.1149978637695","0.000950156777614075"
"0.0466526748143195","1557.30160396793","93.3150024414063","0.000952150432968615"
"0.0467488137037149","1559.45902338575","93.5149993896484","0.000954995361041263"
"0.0468543299847818","1562.4831866584","93.7149963378906","0.000958465548817941"
"0.0469574996262906","1565.04302286596","93.9150009155273","0.000957857977711654"
"0.0470512964594083","1567.01756547752","94.1149978637695","0.000962199704899401"
"0.0471521240446394","1569.39869613852","94.3150024414063","0.000962275687094565"
"0.0472552936861482","1572.05721556866","94.5149993896484","0.000964556012314554"
"0.0473514325755436","1573.98433754379","94.7149963378906","0.000966344709099292"
"0.0474522601607747","1576.34801477609","94.9150009155273","0.000969775509310146"
"0.0475554343855639","1579.29676606442","95.1149978637695","0.000974836739904878"
"0.047653915331237","1581.37021143854","95.3150024414063","0.000978070530672851"
"0.04775239627691","1583.68196746476","95.5149993896484","0.000977601102501975"
"0.0478579171412573","1586.41666726917","95.7149963378906","0.000983533371211484"
"0.0479563980869304","1588.58012403653","95.9150009155273","0.000984084725519276"
"0.0480548790326034","1590.70658831667","96.1149978637695","0.000987978866731741"
"0.0481603998969507","1593.4264691722","96.3150024414063","0.000991339199006646"
"0.048423017279839","-130.665930868278","96.4940032958984","-0.0140666065638606"