File: MATLAB/ASEN 1022/Data1.csv
"File Path: C:\Users\chts4244\Desktop\Test Run 1 03-19-19 10 18 26 AM\DAQ- Crosshead, … - (Timed).csv   "
"Test: MTS EM Tension (ASEN 1022 Extensometer) 10"
"Test Run: Test Run 1"
"Date: 3/19/2019 10:15:59 AM"
""
""
"Crosshead ","Load ","Time ","Extensometer "
"in","lbf","sec","in"
"0.000879310076509962","227.725806205432","0.248000234365463","7.31454444869846E-05"
"0.00194620622819708","322.008267490131","0.448000103235245","0.0001482332778309"
"0.00296386104768259","413.87801179871","0.647999942302704","0.000209168653001809"
"0.00397917108956768","504.262815101421","0.848000168800354","0.000258317943623447"
"0.00498041189294015","576.617595392061","1.04799997806549","0.000299278093820693"
"0.00598868774525147","651.778371096757","1.24800026416779","0.000353073971389562"
"0.00698523899342307","725.200225477179","1.44800007343292","0.000408528047576217"
"0.00799116992490645","798.32597530486","1.64800000190735","0.000460669271408225"
"0.00898772117307806","869.282944520583","1.84800016880035","0.000509892342102028"
"0.00999599702538937","938.961093332442","2.04800009727478","0.000559881071268588"
"0.010987857858995","1004.68818106133","2.2480001449585","0.00060922115883977"
"0.0119750299967649","1066.7413769364","2.44800019264221","0.000657039597322504"
"0.0129856513428142","1127.54967133506","2.64800000190735","0.00070470048554194"
"0.0139915817013876","1185.82052260448","2.84800004959106","0.000755036075935904"
"0.0149810981870754","1241.99147393176","3.04800009727478","0.000801705901385432"
"0.0159823398498129","1298.1882212071","3.2480001449585","0.000843883181076981"
"0.0169999942396159","1355.13338028618","3.44800019264221","0.00089396969882742"
"0.0180106144398451","1409.5465847356","3.64800000190735","0.000940621405996668"
"0.019000132071353","1461.44572706402","3.84800004959106","0.000978861003312077"
"0.0199919940507787","1512.23816833563","4.0479998588562","0.00102235805291378"
"0.021002614251008","1563.93017468962","4.2480001449585","0.00106179846969055"
"0.0219850954013019","1611.692854419","4.44799995422363","0.00110256023188012"
"0.0229957156015311","1660.98693530326","4.64799976348877","0.00114485782268182"
"0.0239875787267769","1707.29000345237","4.84800004959106","0.00118007789758734"
"0.025000543274924","1754.02358950911","5.0479998588562","0.00122134109929673"
"0.0259900597606118","1796.7207134293","5.2480001449585","0.00125602321166684"
"0.027000679960841","1839.41684941957","5.44799995422363","0.00128874095870864"
"0.0279948874340048","1879.26774722373","5.64799976348877","0.00132393009647155"
"0.0289890949071686","1918.53071695209","5.84800004959106","0.00135862653159287"
"0.0299809557407742","1956.01782775395","6.0479998588562","0.0013890903072769"
"0.030975163213938","1993.58529018977","6.2480001449585","0.00142197878151311"
"0.0319975074453969","2032.77866574336","6.44799995422363","0.00145414080580799"
"0.0330010923102322","2069.86445745539","6.64799976348877","0.00148749391009342"
"0.0340117125104614","2108.70942305517","6.84800004959106","0.00152262289230125"
"0.0350059199836252","2146.62200234504","7.0479998588562","0.00155432100268448"
"0.0360048161526247","2185.23359694237","7.2480001449585","0.00158812269553777"
"0.0369990213341483","2222.19600718368","7.44799995422363","0.00162053823252905"
"0.0379908844593942","2260.62648129462","7.64799976348877","0.0016557467060061"
"0.0389991603117055","2299.5910961854","7.84800004959106","0.00169182242206884"
"0.0400004008286229","2338.02596109602","8.04800033569336","0.00172764190411247"
"0.0409946060101465","2375.92163580716","8.2480001449585","0.001763904675306"
"0.0420028818624578","2415.45551787515","8.44799995422363","0.00179806214529933"
"0.0429970870439814","2453.87172188717","8.64799976348877","0.00183384410173478"
"0.043993638865063","2492.25016502202","8.84800052642822","0.00186943513589662"
"0.0449831553507508","2530.666808114","9.04800033569336","0.00190653278025813"
"0.045998466538456","2570.96995828416","9.2480001449585","0.00194647850369756"
"0.0469739169366364","2607.41008290473","9.44799995422363","0.00198035281289948"
"0.048003294211849","2649.89370419097","9.64799976348877","0.00202015287395911"
"0.048988122001701","2687.06533603655","9.84800052642822","0.00205699729207925"
"0.0500174992769135","2729.28572888258","10.0480003356934","0.00210155164717521"
"0.0509999850104878","2767.38074589874","10.2480001449585","0.00213809987080034"
"0.0520012255274053","2806.99497960069","10.4479999542236","0.00217519035378625"
"0.052988395373535","2846.30580904545","10.6479997634888","0.00221604285060472"
"0.0540060532007982","2887.10490003833","10.8480005264282","0.00225815975989992"
"0.0550002583823218","2926.42253522258","11.0480003356934","0.0022973596976839"
"0.0559944635638454","2965.36190301526","11.2480001449585","0.00233955781697846"
"0.056991015384927","3005.68722672376","11.4479999542236","0.00238153092585152"
"0.0580039799330741","3046.13417558311","11.6479997634888","0.00242164494161765"
"0.0589981851145977","3086.08935487943","11.8480005264282","0.00246795984929222"
"0.0599947369356794","3125.01598935307","12.0480003356934","0.00251188400333498"
"0.0609983240921549","3165.85459754298","12.2480001449585","0.00255440252257408"
"0.0619995646090723","3205.71054476676","12.4479999542236","0.002599939704858"
"0.0629890810947601","3244.41324845723","12.6479997634888","0.00264811886182994"
"0.063980944220006","3282.63076878418","12.8480005264282","0.00269455207542949"
"0.0649845313764815","3323.2750840887","13.0480003356934","0.00274453332095854"
"0.0660115665954164","3364.29700816482","13.2480001449585","0.00280022791194488"
"0.0670081138332176","3402.36721716285","13.4479999542236","0.00285059902276184"
"0.0679976349021858","3439.65805921946","13.6479997634888","0.0029017378330436"
"0.0690082528107748","3479.23475158424","13.8480005264282","0.00295841782931312"
"0.0699907339610687","3514.60264292541","14.0480003356934","0.00301363117585883"
"0.0709966677571024","3552.12729506445","14.2480001449585","0.00306620913618208"
"0.0719908729386259","3587.05632597862","14.4479999542236","0.00311838577301645"
"0.073003837486773","3622.76977325382","14.6479997634888","0.00317287782581127"
"0.0739957006120189","3655.00285317065","14.8480005264282","0.0032329520276623"
"0.0750063185206079","3686.70464632743","15.0480003356934","0.00330331999080725"
"0.0760005282854119","3715.2180603039","15.2480001449585","0.00339107806556015"
"0.0770064529148847","3741.8368442228","15.4479999542236","0.0034940205482348"
"0.0779936273442948","3765.40885225075","15.6479997634888","0.00360686749982552"
"0.0789972190840507","3787.3312368427","15.8480005264282","0.00373453534791231"
"0.0800008016572459","3807.83539314128","16.0480003356934","0.00388539258957159"
"0.0809856294470979","3824.34260450033","16.2480010986328","0.00405933123125922"
"0.0820056293306388","3841.72314591373","16.4479999542236","0.00427565060731933"
"0.0830139051829501","3854.78840941153","16.6480007171631","0.00451696060614396"
"0.0840057637249156","3866.86662114353","16.8479995727539","0.00477995038056365"
"0.0850023155459973","3876.88774323018","17.0480003356934","0.00506292812720557"
"0.0859941740879628","3886.14662249414","17.2480010986328","0.00535693811619376"
"0.0870047965798322","3894.6151578175","17.4479999542236","0.00567579750561955"
"0.0880130724321435","3902.22616996534","17.6480007171631","0.00600897277133378"
"0.0890025935011117","3907.65232019742","17.8479995727539","0.00635375863208809"
"0.0900038294347487","3913.29274145339","18.0480003356934","0.00671223933463843"
"0.0910050745349465","3918.40582766901","18.2480010986328","0.0070889179519649"
"0.0920110037476998","3923.09695803635","18.4479999542236","0.00748128456514563"
"0.0929958315375518","3926.65789656865","18.6480007171631","0.00787747535289918"
"0.0940041073898631","3931.28975114045","18.8479995727539","0.00829138395680833"
"0.0949983125713867","3934.27505583602","19.0480003356934","0.00871112879538014"
"0.0960206590944857","3938.45729252162","19.2480010986328","0.0091555328282535"
"0.0969867229344338","3939.4245856889","19.4479999542236","0.00959204273357049"
"0.0980114160970909","3944.2891526432","19.6480007171631","0.0100495331777685"
"0.0990056212786145","3946.20837117892","19.8479995727539","0.0105218562631186"
"0.100006866378812","3949.14757247796","20.0480003356934","0.0110032404937935"
"0.100998724920778","3952.219815007","20.2480010986328","0.0114792886402781"
"0.102011694052205","3955.03124403565","20.4479999542236","0.0119731290812245"
"0.103008245873287","3957.38954253836","20.6480007171631","0.0124638104961642"
"0.104004797694369","3959.20821176164","20.8479995727539","0.0129539911877217"
"0.104996656236334","3962.26903821154","21.0480003356934","0.0134396768270398"
"0.106007278728204","3964.79111354194","21.2480010986328","0.0139357229716724"
"0.107003830549285","3967.65874480636","21.4479999542236","0.0144238285830347"
"0.108002719843364","3969.72900685073","21.6480007171631","0.0149100917156815"
"0.109008649056117","3973.24252474659","21.8479995727539","0.0153958231878034"
"0.110012240795873","3975.23726503664","22.0480003356934","0.0158846689989482"
"0.111001752698281","3976.98612054516","22.2480010986328","0.0163570287505414"
"0.11200065115892","3979.39798680385","22.4479999542236","0.016836513211496"
"0.11299954961956","3982.27791230735","22.6480007171631","0.01730793453643"
"0.114003132192755","3984.58835109366","22.8479995727539","0.017773717280668"
"0.115009061405509","3987.87574280652","23.0480003356934","0.0182443262191533"
"0.116003275753593","3989.90868305369","23.2480010986328","0.0187057468262831"
"0.117018582358018","3993.1157231326","23.4479999542236","0.0191741042282784"
"0.117998716868754","3994.03208302371","23.6480007171631","0.0196288699122864"
"0.119006992721065","3996.83912125269","23.8479995727539","0.0200815032250945"
"0.119996513790033","3999.22332547346","24.0480003356934","0.0205296632562449"
"0.121007136281902","4002.38514031576","24.2480010986328","0.0209845217516807"
"0.122001341463426","4004.33948524884","24.4479999542236","0.0214300578548096"
"0.123014301428293","4007.52764488917","24.6480007171631","0.0218779749720995"
"0.124006169136819","4009.91975254934","24.8479995727539","0.0223192829990716"
"0.125012098349572","4012.10680986492","25.0480003356934","0.0227663224181674"
"0.125994579499866","4013.91098944929","25.2480010986328","0.0232003796955673"
"0.126998162073061","4016.38125334359","25.4479999542236","0.0236431612471837"
"0.128004091285814","4019.5483371455","25.6480007171631","0.0240812472280438"
"0.12900768302557","4021.42145228468","25.8479995727539","0.0245260889641941"
"0.130004234846652","4024.44846957712","26.0480003356934","0.0249588560481651"
"0.131010164059405","4026.87438639475","26.2480010986328","0.0253965868247952"
"0.132004369240929","4029.1936067804","26.4479999542236","0.0258301032751095"
"0.133003267701569","4031.00656796411","26.6480007171631","0.0262677698858141"
"0.133995126243534","4033.82107055253","26.8479995727539","0.0266952776555412"
"0.135003402095845","4036.04588874527","27.0480003356934","0.0271318351123922"
"0.136006993835601","4039.17125995032","27.2480010986328","0.0275605666179826"
"0.137001199017125","4040.50606304997","27.4479999542236","0.0279898022844155"
"0.138007128229878","4043.48522062601","27.6480007171631","0.0284208575131621"
"0.139006026690518","4045.51596547335","27.8479995727539","0.0288496577679583"
"0.140007262624155","4048.06043388207","28.0480003356934","0.0292820765226199"
"0.14099912116612","4049.66044128178","28.2480010986328","0.029704632057889"
"0.142005059545434","4053.00710879019","28.4479999542236","0.0301307740100608"
"0.143001611366516","4054.40733480493","28.6480007171631","0.0305552545230924"
"0.144016917970941","4057.83523210723","28.8479995727539","0.0309889886792251"
"0.144994715008679","4058.40164526465","29.0480003356934","0.031404529503862"
"0.146010021613104","4061.67235193877","29.2480010986328","0.0318302016697941"
"0.146997196042514","4063.40979136816","29.4479999542236","0.0322482014243586"
"0.148005471894826","4065.84580702503","29.6480007171631","0.0326732823471209"
"0.148997330436791","4068.24537904464","29.8479995727539","0.0330858211231044"
"0.150012637041216","4070.75823369573","30.0480003356934","0.0335098799743404"
"0.151004504749742","4072.37624337409","30.2480010986328","0.0339252328844814"
"0.152003394043821","4074.11719544322","30.4479999542236","0.0343351500240837"
"0.152995261752347","4076.67307993107","30.6480007171631","0.0347441230079262"
"0.154005884244217","4078.19537017663","30.8479995727539","0.0351613252717034"
"0.155002436065298","4080.94049813027","31.0480003356934","0.0355721109429389"
"0.15599898788638","4082.33325978556","31.2480010986328","0.03598402868443"
"0.157009601211689","4085.90649255694","31.4479999542236","0.0364010934497956"
"0.158010846311886","4087.21582901851","31.6480007171631","0.036818002383628"
"0.159002704853852","4088.68235610826","31.8479995727539","0.0372258501721355"
"0.16000394995405","4090.70080671652","32.0480003356934","0.037638423322722"
"0.161005195054248","4093.10959941544","32.2480010986328","0.0380469975611708"
"0.162004075181766","4094.32716816391","32.4480018615723","0.0384577923989671"
"0.163005320281964","4097.11049607467","32.6479988098145","0.0388635135453752"
"0.164001872103045","4098.63454264009","32.8479995727539","0.0392738592216936"
"0.16501717870747","4101.77396440408","33.0480003356934","0.0396847365585368"
"0.165999669024325","4101.881538996","33.2480010986328","0.0400958888922033"
"0.167003260764081","4104.0949411096","33.4480018615723","0.0404991442337632"
"0.167995119306046","4105.73622202622","33.6479988098145","0.0409051037107514"
"0.169010425910471","4108.04095277296","33.8479995727539","0.0413210776553849"
"0.169995262866884","4109.0060505404","34.0480003356934","0.04172415883229"
"0.171010569471309","4112.01550463416","34.2480010986328","0.0421333586885117"
"0.172002428013274","4113.29059285831","34.4480018615723","0.0425383327602167"
"0.173013041338583","4115.24230331159","34.6479988098145","0.0429543983704579"
"0.173990838376321","4116.02474381276","34.8479995727539","0.0433569295537167"
"0.174996776755635","4117.92025203027","35.0480003356934","0.0437617386273277"
"0.176007390080944","4120.53541231367","35.2480010986328","0.044170246408211"
"0.177003941902025","4120.79929937383","35.4480018615723","0.0445788137717393"
"0.178002840362665","4123.417533217","35.6479988098145","0.0449817482836721"
"0.179011107048416","4125.15453356642","35.8479995727539","0.0453886015003356"
"0.180005312229939","4126.70931572954","36.0480003356934","0.0457955326327658"
"0.181004210690579","4127.67046177728","36.2480010986328","0.046205034985493"
"0.181996069232545","4129.34467369142","36.4480018615723","0.0466054257768111"
"0.183004354251417","4130.81515250088","36.6479988098145","0.0470134660630949"
"0.184010292630731","4133.10846716847","36.8479995727539","0.0474224413385776"
"0.185004497812254","4133.5510597752","37.0480003356934","0.0478314899465465"
"0.186003377939772","4135.29684172396","37.2480010986328","0.0482372569257584"
"0.187006969679528","4136.55217134959","37.4480018615723","0.0486413097581056"
"0.188008214779726","4137.53483231572","37.6479988098145","0.0490448171800868"
"0.188997726682134","4138.74098498504","37.8479995727539","0.0494482787692641"
"0.190006011701006","4141.31048095188","38.0480003356934","0.049855076986563"
"0.191004910161645","4141.81234935415","38.2480010986328","0.0502654226628814"
"0.192015523486954","4143.90105275713","38.4480018615723","0.0506749387654498"
"0.192990973885134","4143.61125997891","38.6479988098145","0.0510732899969957"
"0.194008627129117","4146.22290762258","38.8479995727539","0.0514843598316152"
"0.194998139031525","4146.38931893007","39.0480003356934","0.0518843977103435"
"0.196004077410839","4147.94717465296","39.2480010986328","0.0522930567394795"
"0.196995935952804","4149.06287684908","39.4480018615723","0.0526913254719785"
"0.198011242557229","4150.9820953848","39.6479988098145","0.0531005024117982"
"0.199007794378311","4151.86815875819","39.8479995727539","0.0535087031128956"
"0.20000669283895","4152.58693266416","40.0480003356934","0.0539113442948836"
"0.200991511462242","4153.52392931372","40.2480010986328","0.0543093517804005"
"0.20200448976023","4154.33491001275","40.4480018615723","0.0547195462084661"
"0.20300338822087","4155.99463228798","40.6479988098145","0.0551217611453782"
"0.204002268348388","4155.8466623391","40.8479995727539","0.0555201444598868"
"0.205008206727702","4158.8209900355","41.0480003356934","0.0559235327165779"
"0.206014145107016","4159.3118814386","41.2480010986328","0.0563335713131104"
"0.207001310369865","4159.52044442292","41.4480018615723","0.0567301350653054"
"0.208002555470063","4160.10178629922","41.6479988098145","0.0571260938244894"
"0.208994414012028","4160.96853015406","41.8479995727539","0.0575217913366913"
"0.210002680697779","4161.83483492893","42.0480003356934","0.0579243775193147"
"0.211001579158419","4163.17929778786","42.2480010986328","0.0583201483640028"
"0.212002824258617","4163.72243970703","42.4480018615723","0.0587145213081729"
"0.213015784223483","4165.66317316113","42.6479988098145","0.0591195045464386"
"0.214000621179896","4164.8482407424","42.8479995727539","0.0595178466114238"
"0.215004212919652","4165.94681881981","43.0480003356934","0.0599061100428381"
"0.215996071461617","4166.26998167552","43.2480010986328","0.0602969034450261"
"0.217006684786926","4167.41510222943","43.4480018615723","0.0606929722029393"
"0.217996196689334","4166.85395803162","43.6479988098145","0.0610845493460734"
"0.219013849933316","4169.23377145271","43.8479995727539","0.0614760760731232"
"0.219998686889729","4168.8522109614","44.0480003356934","0.0618607737123966"
"0.221009300215038","4170.09919806765","44.2480010986328","0.0622538495882172"
"0.221991790531892","4169.73256629521","44.4480018615723","0.0626331068736714"
"0.223002403857201","4170.69327326299","44.6479988098145","0.0630190328320884"
"0.224003648957399","4171.34618517391","44.8479995727539","0.0633977080409334"
"0.225007240697155","4171.13850034952","45.0480003356934","0.0637831023388256"
"0.226006139157795","4171.69832730743","45.2480010986328","0.0641519464112408"
"0.227007365924871","4172.07900963882","45.4480018615723","0.0645254745962113"
"0.228006264385511","4172.93302017462","45.6479988098145","0.0648914174521415"
"0.22900516284615","4172.38153573607","45.8479995727539","0.0652602019419116"
"0.229999368027674","4173.007663769","46.0480003356934","0.0656173082332559"
"0.231005306406988","4173.09855332217","46.2480010986328","0.0659766694985506"
"0.232006551507186","4173.98373853563","46.4480018615723","0.0663266992049776"
"0.233003103328267","4173.43884029659","46.6479988098145","0.0666776547340427"
"0.23400902337446","4173.92446274008","46.8479995727539","0.0670217307592471"
"0.234998535276867","4172.72050547059","47.0480003356934","0.0673543989995685"
"0.235997433737507","4173.48406553319","47.2480010986328","0.0676795369102143"
"0.236996332198147","4173.09723608227","47.4480018615723","0.068002470262994"
"0.238006963856577","4173.78307899071","47.6479988098145","0.0683173141258908"
"0.239008190623653","4173.12884983989","47.8479995727539","0.0686274922093538"
"0.240016475642525","4173.01117640874","48.0480003356934","0.0689242687809655"
"0.2409966009867","4170.99140856058","48.2480010986328","0.0692011080828943"
"0.242014272563805","4171.42390232806","48.4480018615723","0.069477117811073"
"0.242999091187096","4169.55912970825","48.6479988098145","0.0697300048896999"
"0.244002682926852","4168.92729363575","48.8479995727539","0.0699758245499702"
"0.244999234747934","4167.9995176655","49.0480003356934","0.0702015281926225"
"0.246014541352358","4166.91762462683","49.2480010986328","0.0704153336393904"
"0.247006399894324","4164.66690071603","49.4480018615723","0.0706042014575732"
"0.248007644994522","4162.45437676236","49.6479988098145","0.0707807310849546"
"0.248999503536487","4160.10222537919","49.8479995727539","0.0709335468196141"
"0.250007770222238","4156.0662023226","50.0480003356934","0.0710714989759791"
"0.250987913899534","4152.70855781501","50.2480010986328","0.0711858564049123"
"0.25199150563929","4149.23850883588","50.4480018615723","0.0712918539304198"
"0.253006812243715","4146.03542047668","50.6479988098145","0.0713753887987512"
"0.254015097262587","4139.41453365441","50.8479995727539","0.0714415072016125"
"0.255009302444111","4133.46719550151","51.0480003356934","0.0714942882585479"
"0.256005854265192","4126.47001714753","51.2480010986328","0.0715354873659456"
"0.257007081032269","4119.13123457923","51.4480018615723","0.0715659570139576"
"0.258008326132466","4110.29958012316","51.6479988098145","0.0715849409613201"
"0.25900253131399","4102.50020266949","51.8479995727539","0.0716014911867972"
"0.260003776414188","4093.04988453993","52.0480003356934","0.0716078711130957"
"0.261021429658171","4083.83623051258","52.2480010986328","0.0716137102123086"
"0.262006266614584","4071.62366031067","52.4480018615723","0.0716087969357339"
"0.263005146742102","4061.15028585802","52.6479988098145","0.0716039524083649"
"0.263999351923625","4049.50939777314","52.8479995727539","0.0715976412312722"
"0.265012330221614","4037.42942972126","53.0480003356934","0.0715874846819348"
"0.265999495484463","4024.21663535455","53.2480010986328","0.0715736890079703"
"0.266991354026428","4013.08068923171","53.4480018615723","0.0715632116290059"
"0.267997292405742","4000.21125539919","53.6479988098145","0.0715480593040468"
"0.269019638928841","3985.88363699628","53.8479995727539","0.0715312936643916"
"0.26999743596658","3971.59904843014","54.0480003356934","0.0715133455383965"
"0.271015089210563","3957.47208957216","54.2480010986328","0.0714921891161307"
"0.272011641031644","3943.7543532434","54.4480018615723","0.0714758726379534"
"0.273010521159163","3928.32464412335","54.6479988098145","0.0714557566203353"
"0.274004744673808","3914.81722709879","54.8479995727539","0.0714400359686083"
"0.27501066472","3899.4344995352","55.0480003356934","0.0714187832974543"
"0.27600956318064","3884.01928005406","55.2480010986328","0.0713971639638693"
"0.27700846164128","3867.55553761174","55.4480018615723","0.0713752238006573"
"0.278000320183245","3852.90080463343","55.6479988098145","0.071353659466437"
"0.279010933508554","3836.72422048953","55.8479995727539","0.0713309447288396"
"0.28001452524831","3820.78166596803","56.0480003356934","0.0713107737118569"
"0.281006383790275","3803.78575860572","56.2480010986328","0.0712847040130163"
"0.282005282250915","3787.70445481465","56.4480018615723","0.0712617463615584"
"0.282990119207328","3769.95815978875","56.6479988098145","0.0712367262339264"
"0.284007772451311","3752.69090100683","56.8479995727539","0.0712121186015292"
"0.284999630993276","3735.56809953406","57.0480003356934","0.0711849259989937"
"0.286007897679027","3718.69732996234","57.2480010986328","0.0711633020821284"
"0.287016182697899","3699.36815165544","57.4480018615723","0.0711348032446827"
"0.288026796023207","3681.7127461827","57.6479988098145","0.0711094531208629"
"0.289004593060946","3662.58269064083","57.8479995727539","0.0710791851371879"
"0.290017553025813","3643.93320812283","58.0480003356934","0.0710525700279812"
"0.291002389982225","3624.56385399894","58.2480010986328","0.0710252170106323"
"0.292015349947092","3605.15893439773","58.4480018615723","0.0709957327679034"
"0.293000186903505","3585.97553063987","58.6479988098145","0.070966111026763"
"0.294013146868372","3565.94711748553","58.8479995727539","0.0709363197042482"
"0.295009698689453","3545.84362165683","59.0480003356934","0.0709078804494476"
"0.296010943789651","3524.85384291477","59.2480010986328","0.0708752520763733"
"0.296974660990041","3504.66055523282","59.4480018615723","0.0708470557354332"
"0.297992314234024","3482.1364115461","59.6479988098145","0.0708125573839611"
"0.298998252613338","3461.86299177018","59.8479995727539","0.0707823489829311"
"0.300013559217763","3438.54850414288","60.0480003356934","0.0707472593882891"
"0.301017132624397","3417.92382039336","60.2480010986328","0.0707182609732813"
"0.302020724364153","3394.2137217158","60.4480018615723","0.0706837855382111"
"0.303019622824793","3370.55587355431","60.6479988098145","0.0706475959562763"
"0.304013828006316","3346.56234875805","60.8479995727539","0.0706112230431259"
"0.305012726466956","3322.46410338966","61.0480003356934","0.0705765413604383"
"0.306009278288038","3297.70811623073","61.2480010986328","0.0705374413954578"
"0.307005830109119","3272.99954970822","61.4480018615723","0.0705004405728945"
"0.308004728569759","3247.36628077524","61.6479988098145","0.070463485583135"
"0.309017706867747","3221.25331697831","61.8479995727539","0.0704240235390039"
"0.310009565409713","3194.0307981048","62.0480003356934","0.0703839702517029"
"0.311013120483226","3166.69345981991","62.2480010986328","0.0703411394964874"
"0.312002669051876","3138.30606179397","62.4480018615723","0.0702992391471905"
"0.312985141035609","3111.82844208446","62.6479988098145","0.0702579896237085"
"0.313986386135807","3080.95475374543","62.8479995727539","0.0702112997464073"
"0.315006367686227","3051.83255539472","63.0480003356934","0.070165627357352"
"0.316016999344657","3019.43218601046","63.2480010986328","0.0701195424730618"
"0.317025284363529","2986.40700583317","63.4480018615723","0.0700680309847936"
"0.318049959193065","1682.24927293484","63.6479988098145","0.0627559937874046"
"0.318636179087669","-25.0750507915146","63.6790008544922","-0.00942850613317592"